Workbook

Sheet 在职
A1: 序号 | B1: 姓名 | C1: 区域 | D1: 部门 | E1: 组别 | F1: 岗位 | G1: 入职日期 | H1: 其他 | I1: 辅助列 | J1: 24年剩余调休 | K1: 24年年假使用情况 | N1: 24年已使用育儿假 | O1: 1月 | X1: 2月 | AG1: 1-2月使用年假 | AH1: 24年剩余年假 | AI1: 截至24.2月剩余年假 | AJ1: 3月 | AS1: 4月 | BB1: 5月 | BK1: 6月 | BT1: 7月 | CC1: 8月 | CL1: 9月 | CV1: 10月 | DE1: 11月 | DN1: 12月 | DW1: 25年年假使用情况 | DZ1: 25年总加班情况 | ED1: 25年总请假
K2: 总年假 | L2: 已使用年假 | M2: 剩余年假 | O2: 年假 | P2: 事假h | Q2: 病假 | R2: 其他 | S2: 调休 | T2: 加班 加班费 | U2: 加班 转调休 | V2: 育儿假 | W2: 备注 | X2: 年假 | Y2: 事假h | Z2: 病假 | AA2: 其他 | AB2: 调休 | AC2: 加班 加班费 | AD2: 加班 转调休 | AE2: 育儿假 | AF2: 备注 | AJ2: 年假 | AK2: 事假h | AL2: 病假 | AM2: 其他 | AN2: 调休 | AO2: 加班 加班费 | AP2: 加班 转调休 | AQ2: 育儿假 | AR2: 备注 | AS2: 年假 | AT2: 事假h | AU2: 病假 | AV2: 其他 | AW2: 调休 | AX2: 加班 加班费 | AY2: 加班 转调休 | AZ2: 育儿假 | BA2: 备注 | BB2: 年假 | BC2: 事假h | BD2: 病假 | BE2: 其他 | BF2: 调休 | BG2: 加班 加班费 | BH2: 加班 转调休 | BI2: 育儿假 | BJ2: 备注 | BK2: 年假 | BL2: 事假h | BM2: 病假 | BN2: 其他 | BO2: 调休 | BP2: 加班 加班费 | BQ2: 加班 转调休 | BR2: 育儿假 | BS2: 备注 | BT2: 年假 | BU2: 事假h | BV2: 病假 | BW2: 其他 | BX2: 调休 | BY2: 加班 加班费 | BZ2: 加班 转调休 | CA2: 育儿假 | CB2: 备注 | CC2: 年假 | CD2: 事假h | CE2: 病假 | CF2: 其他 | CG2: 调休 | CH2: 加班 加班费 | CI2: 加班 转调休 | CJ2: 育儿假 | CK2: 备注 | CL2: 年假 | CM2: 事假h | CN2: 病假 | CO2: 其他 | CP2: 调休 | CQ2: 加班 加班费 | CR2: 加班 转调休 | CS2: 育儿假 | CT2: 备注 | CU2: 折算调休数 | CV2: 年假 | CW2: 事假h | CX2: 病假 | CY2: 其他 | CZ2: 调休 | DA2: 加班 加班费 | DB2: 加班 转调休 | DC2: 育儿假 | DD2: 备注 | DE2: 年假 | DF2: 事假h | DG2: 病假 | DH2: 其他 | DI2: 调休 | DJ2: 加班 加班费 | DK2: 加班 转调休 | DL2: 育儿假 | DM2: 备注 | DN2: 年假 | DO2: 事假h | DP2: 病假 | DQ2: 其他 | DR2: 调休 | DS2: 加班 加班费 | DT2: 加班 转调休 | DU2: 育儿假 | DV2: 备注 | DW2: 总年假 | DX2: 已使用 年假 | DY2: 剩余年假 | DZ2: 累计 加班/天 | EA2: 已调 休/天 | EB2: 剩余调休 | EC2: 累计计薪加班/h | ED2: 累计 事假 | EE2: 累计 病假 | EF2: 累计 其他 | EG2: 累计 育儿假
A3: =ROW()-2 -> 1 | B3: 刘其坚 | C3: 上海 | D3: 总经办 | E3: / | F3: CEO | G3: 41933 | H3: 45292 | I3: 45658 | J3: 0 | K3: =ROUND((I3-H3)/365*5,0) -> 5 | L3: 0 | M3: =K3-L3 -> 5 | AG3: =O3+X3 -> 0 | AH3: =M3-AG3 -> 5 | AI3: =IF(AH3<0,AH3,0) -> 0 | DW3: =ROUND((TODAY()-I3)/365*5,2) -> 5.05 | DX3: =-AI3+AJ3+AS3+BB3+BK3+BT3+CC3+CL3+CV3+DE3+DN3 -> 0 | DY3: =DW3-DX3 -> 5.05 | DZ3: =T3+U3+AC3+AD3+AO3+AP3+AX3+AY3++BG3+BH3+BP3+BQ3+BY3+BZ3+CH3+CI3+CQ3+CR3+DA3+DB3+DJ3+DK3+DS3+DT3 -> 0 | EA3: =S3+AB3+AN3+AW3+BF3+BO3+BX3+CG3+CP3+CZ3+DI3+DR3 -> 0 | EB3: =J3+U3-S3+AD3-AB3+AP3-AN3+AY3-AW3+BH3-BF3+BQ3-BO3+BZ3-BX3+CI3-CG3+CR3-CP3+DB3-CZ3+DK3-DI3+DT3-DR3-CU3 -> 0 | EC3: =T3+AC3+AO3+BG3+BP3+BY3+CH3+CQ3+DA3+DA3+DJ3+DS3 -> 0 | ED3: =P3+Y3+AK3+AT3+BC3+BL3+BU3+CD3+CM3+CW3+DF3+DO3 -> 0 | EE3: =Q3+Z3+AL3+AU3+BD3+BM3+BV3+CE3+CN3+CX3+DG3+DP3 -> 0 | EF3: =R3+AA3+AM3+AV3+BE3+BN3+BW3+CF3+CO3+CY3+DH3+DQ3 -> 0 | EG3: =V3+AE3+AQ3+AZ3+BI3+BR3+CA3+CJ3+CS3+DC3+DL3+DU3 -> 0
A4: =ROW()-2 -> 2 | B4: 刘玉 | C4: 上海 | D4: 财务部 | E4: / | F4: 财务专员 | G4: 43563 | H4: 45292 | I4: 45658 | J4: 13 | K4: =ROUND((I4-H4)/365*5,0) -> 5 | L4: 2.5 | M4: =K4-L4 -> 2.5 | O4: 2 | X4: 1 | AD4: 8 | AG4: =O4+X4 -> 3 | AH4: =M4-AG4 -> -0.5 | AI4: =IF(AH4<0,AH4,0) -> -0.5 | AP4: 8 | AS4: 1 | BO4: 5 | BQ4: 3.5 | CH4: 8 | DA4: 8 | DJ4: 5 | DK4: 6 | DW4: =ROUND((TODAY()-I4)/365*5,2) -> 5.05 | DX4: =-AI4+AJ4+AS4+BB4+BK4+BT4+CC4+CL4+CV4+DE4+DN4 -> 1.5 | DY4: =DW4-DX4 -> 3.55 | DZ4: =T4+U4+AC4+AD4+AO4+AP4+AX4+AY4++BG4+BH4+BP4+BQ4+BY4+BZ4+CH4+CI4+CQ4+CR4+DA4+DB4+DJ4+DK4+DS4+DT4 -> 46.5 | EA4: =S4+AB4+AN4+AW4+BF4+BO4+BX4+CG4+CP4+CZ4+DI4+DR4 -> 5 | EB4: =J4+U4-S4+AD4-AB4+AP4-AN4+AY4-AW4+BH4-BF4+BQ4-BO4+BZ4-BX4+CI4-CG4+CR4-CP4+DB4-CZ4+DK4-DI4+DT4-DR4-CU4 -> 33.5 | EC4: =T4+AC4+AO4+BG4+BP4+BY4+CH4+CQ4+DA4+DA4+DJ4+DS4 -> 29 | ED4: =P4+Y4+AK4+AT4+BC4+BL4+BU4+CD4+CM4+CW4+DF4+DO4 -> 0 | EE4: =Q4+Z4+AL4+AU4+BD4+BM4+BV4+CE4+CN4+CX4+DG4+DP4 -> 0 | EF4: =R4+AA4+AM4+AV4+BE4+BN4+BW4+CF4+CO4+CY4+DH4+DQ4 -> 0 | EG4: =V4+AE4+AQ4+AZ4+BI4+BR4+CA4+CJ4+CS4+DC4+DL4+DU4 -> 0
A5: =ROW()-2 -> 3 | B5: 胡生娜 | C5: 上海 | D5: 财务部 | E5: / | F5: 财务总监 | G5: 43983 | H5: 45292 | I5: 45658 | J5: 0 | K5: =ROUND((I5-H5)/365*5,0) -> 5 | L5: 5 | M5: =K5-L5 -> 0 | O5: 0.5 | P5: 0.5 | X5: 0.5 | AG5: =O5+X5 -> 1 | AH5: =M5-AG5 -> -1 | AI5: =IF(AH5<0,AH5,0) -> -1 | AN5: 2 | AP5: 4 | AS5: 1 | AW5: 3 | AY5: 6 | BB5: 1 | BQ5: 5 | BV5: 0.5 | BX5: 10 | CC5: 1 | CZ5: 1 | DB5: 6.5 | DI5: 2 | DP5: 0.5 | DR5: 2 | DS5: 17 | DW5: =ROUND((TODAY()-I5)/365*5,2) -> 5.05 | DX5: =-AI5+AJ5+AS5+BB5+BK5+BT5+CC5+CL5+CV5+DE5+DN5 -> 4 | DY5: =DW5-DX5 -> 1.05 | DZ5: =T5+U5+AC5+AD5+AO5+AP5+AX5+AY5++BG5+BH5+BP5+BQ5+BY5+BZ5+CH5+CI5+CQ5+CR5+DA5+DB5+DJ5+DK5+DS5+DT5 -> 38.5 | EA5: =S5+AB5+AN5+AW5+BF5+BO5+BX5+CG5+CP5+CZ5+DI5+DR5 -> 20 | EB5: =J5+U5-S5+AD5-AB5+AP5-AN5+AY5-AW5+BH5-BF5+BQ5-BO5+BZ5-BX5+CI5-CG5+CR5-CP5+DB5-CZ5+DK5-DI5+DT5-DR5-CU5 -> 1.5 | EC5: =T5+AC5+AO5+BG5+BP5+BY5+CH5+CQ5+DA5+DA5+DJ5+DS5 -> 17 | ED5: =P5+Y5+AK5+AT5+BC5+BL5+BU5+CD5+CM5+CW5+DF5+DO5 -> 0.5 | EE5: =Q5+Z5+AL5+AU5+BD5+BM5+BV5+CE5+CN5+CX5+DG5+DP5 -> 1 | EF5: =R5+AA5+AM5+AV5+BE5+BN5+BW5+CF5+CO5+CY5+DH5+DQ5 -> 0 | EG5: =V5+AE5+AQ5+AZ5+BI5+BR5+CA5+CJ5+CS5+DC5+DL5+DU5 -> 0
A6: =ROW()-2 -> 4 | B6: 邓雅芳 | C6: 上海 | D6: 财务部 | E6: / | F6: 财务主管 | G6: 44531 | H6: 45292 | I6: 45658 | J6: 1.5 | K6: =ROUND((I6-H6)/365*5,0) -> 5 | L6: 5 | M6: =K6-L6 -> 0 | O6: 1 | S6: 6 | U6: 14.5 | X6: 3 | Y6: 1 | AB6: 9.5 | AG6: =O6+X6 -> 4 | AH6: =M6-AG6 -> -4 | AI6: =IF(AH6<0,AH6,0) -> -4 | AN6: 1 | AP6: 12.5 | AQ6: 1 | AW6: 1 | AX6: 7 | AY6: 6.5 | AZ6: 1 | BF6: 9 | BO6: 3 | BP6: 7 | BR6: 3 | BU6: 1 | BX6: 5.5 | CC6: 1 | CD6: 17 | CM6: 10 | CZ6: 2.5 | DB6: 5 | DC6: 1 | DF6: 21.5 | DI6: 1 | DO6: 2.5 | DS6: 11 | DW6: =ROUND((TODAY()-I6)/365*5,2) -> 5.05 | DX6: =-AI6+AJ6+AS6+BB6+BK6+BT6+CC6+CL6+CV6+DE6+DN6 -> 5 | DY6: =DW6-DX6 -> 0.05 | DZ6: =T6+U6+AC6+AD6+AO6+AP6+AX6+AY6++BG6+BH6+BP6+BQ6+BY6+BZ6+CH6+CI6+CQ6+CR6+DA6+DB6+DJ6+DK6+DS6+DT6 -> 63.5 | EA6: =S6+AB6+AN6+AW6+BF6+BO6+BX6+CG6+CP6+CZ6+DI6+DR6 -> 38.5 | EB6: =J6+U6-S6+AD6-AB6+AP6-AN6+AY6-AW6+BH6-BF6+BQ6-BO6+BZ6-BX6+CI6-CG6+CR6-CP6+DB6-CZ6+DK6-DI6+DT6-DR6-CU6 -> 1.5 | EC6: =T6+AC6+AO6+BG6+BP6+BY6+CH6+CQ6+DA6+DA6+DJ6+DS6 -> 18 | ED6: =P6+Y6+AK6+AT6+BC6+BL6+BU6+CD6+CM6+CW6+DF6+DO6 -> 53 | EE6: =Q6+Z6+AL6+AU6+BD6+BM6+BV6+CE6+CN6+CX6+DG6+DP6 -> 0 | EF6: =R6+AA6+AM6+AV6+BE6+BN6+BW6+CF6+CO6+CY6+DH6+DQ6 -> 0 | EG6: =V6+AE6+AQ6+AZ6+BI6+BR6+CA6+CJ6+CS6+DC6+DL6+DU6 -> 6
A7: =ROW()-2 -> 5 | B7: 周彤 | C7: 上海 | D7: 行政部 | E7: / | F7: 行政前台 | G7: 43549 | H7: 45292 | I7: 45658 | J7: 5 | K7: =ROUND((I7-H7)/365*5,0) -> 5 | L7: 3 | M7: =K7-L7 -> 2 | X7: 2 | AG7: =O7+X7 -> 2 | AH7: =M7-AG7 -> 0 | AI7: =IF(AH7<0,AH7,0) -> 0 | AJ7: 0.5 | AN7: 2 | AP7: 14.5 | AW7: 1 | BT7: 1.5 | BX7: 0.5 | BZ7: 16 | CL7: 1.5 | CZ7: 4 | DB7: 5.5 | DI7: 2 | DR7: 1.5 | DT7: 16 | DW7: =ROUND((TODAY()-I7)/365*5,2) -> 5.05 | DX7: =-AI7+AJ7+AS7+BB7+BK7+BT7+CC7+CL7+CV7+DE7+DN7 -> 3.5 | DY7: =DW7-DX7 -> 1.55 | DZ7: =T7+U7+AC7+AD7+AO7+AP7+AX7+AY7++BG7+BH7+BP7+BQ7+BY7+BZ7+CH7+CI7+CQ7+CR7+DA7+DB7+DJ7+DK7+DS7+DT7 -> 52 | EA7: =S7+AB7+AN7+AW7+BF7+BO7+BX7+CG7+CP7+CZ7+DI7+DR7 -> 11 | EB7: =J7+U7-S7+AD7-AB7+AP7-AN7+AY7-AW7+BH7-BF7+BQ7-BO7+BZ7-BX7+CI7-CG7+CR7-CP7+DB7-CZ7+DK7-DI7+DT7-DR7-CU7 -> 46 | EC7: =T7+AC7+AO7+BG7+BP7+BY7+CH7+CQ7+DA7+DA7+DJ7+DS7 -> 0 | ED7: =P7+Y7+AK7+AT7+BC7+BL7+BU7+CD7+CM7+CW7+DF7+DO7 -> 0 | EE7: =Q7+Z7+AL7+AU7+BD7+BM7+BV7+CE7+CN7+CX7+DG7+DP7 -> 0 | EF7: =R7+AA7+AM7+AV7+BE7+BN7+BW7+CF7+CO7+CY7+DH7+DQ7 -> 0 | EG7: =V7+AE7+AQ7+AZ7+BI7+BR7+CA7+CJ7+CS7+DC7+DL7+DU7 -> 0
A8: =ROW()-2 -> 6 | B8: 张晓伟 | C8: 上海 | D8: 行政部 | E8: / | F8: IT网络工程师 | G8: 43577 | H8: 45292 | I8: 45658 | J8: 37 | K8: =ROUND((I8-H8)/365*5,0) -> 5 | L8: 5 | M8: =K8-L8 -> 0 | U8: 8 | AG8: =O8+X8 -> 0 | AH8: =M8-AG8 -> 0 | AI8: =IF(AH8<0,AH8,0) -> 0 | AN8: 5.5 | AP8: 9 | AW8: 1 | AY8: 2 | BH8: 8 | BQ8: 8 | BZ8: 16 | CG8: 1.5 | CI8: 9.5 | CL8: 4 | CR8: 8 | CV8: 0.5 | CZ8: 8 | DR8: 8 | DT8: 16 | DW8: =ROUND((TODAY()-I8)/365*5,2) -> 5.05 | DX8: =-AI8+AJ8+AS8+BB8+BK8+BT8+CC8+CL8+CV8+DE8+DN8 -> 4.5 | DY8: =DW8-DX8 -> 0.55 | DZ8: =T8+U8+AC8+AD8+AO8+AP8+AX8+AY8++BG8+BH8+BP8+BQ8+BY8+BZ8+CH8+CI8+CQ8+CR8+DA8+DB8+DJ8+DK8+DS8+DT8 -> 84.5 | EA8: =S8+AB8+AN8+AW8+BF8+BO8+BX8+CG8+CP8+CZ8+DI8+DR8 -> 24 | EB8: =J8+U8-S8+AD8-AB8+AP8-AN8+AY8-AW8+BH8-BF8+BQ8-BO8+BZ8-BX8+CI8-CG8+CR8-CP8+DB8-CZ8+DK8-DI8+DT8-DR8-CU8 -> 97.5 | EC8: =T8+AC8+AO8+BG8+BP8+BY8+CH8+CQ8+DA8+DA8+DJ8+DS8 -> 0 | ED8: =P8+Y8+AK8+AT8+BC8+BL8+BU8+CD8+CM8+CW8+DF8+DO8 -> 0 | EE8: =Q8+Z8+AL8+AU8+BD8+BM8+BV8+CE8+CN8+CX8+DG8+DP8 -> 0 | EF8: =R8+AA8+AM8+AV8+BE8+BN8+BW8+CF8+CO8+CY8+DH8+DQ8 -> 0 | EG8: =V8+AE8+AQ8+AZ8+BI8+BR8+CA8+CJ8+CS8+DC8+DL8+DU8 -> 0
A9: =ROW()-2 -> 7 | B9: 卢佳 | C9: 上海 | D9: 行政部 | E9: / | F9: 行政主管 | G9: 44144 | H9: 45292 | I9: 45658 | J9: 0 | K9: =ROUND((I9-H9)/365*5,0)*2 -> 10 | L9: 10 | M9: =K9-L9 -> 0 | U9: 3 | X9: 5 | AG9: =O9+X9 -> 5 | AH9: =M9-AG9 -> -5 | AI9: =IF(AH9<0,AH9,0) -> -5 | AS9: 0.5 | AW9: 1 | BD9: 0.5 | BT9: 4.5 | BU9: 4 | BX9: 2 | CD9: 24 | CW9: 1.5 | CZ9: 2 | DB9: 2 | DF9: 2 | DR9: 2.5 | DT9: 18.5 | DW9: =ROUND((TODAY()-I9)/365*5,2)*2 -> 10.1 | DX9: =-AI9+AJ9+AS9+BB9+BK9+BT9+CC9+CL9+CV9+DE9+DN9 -> 10 | DY9: =DW9-DX9 -> 0.1 | DZ9: =T9+U9+AC9+AD9+AO9+AP9+AX9+AY9++BG9+BH9+BP9+BQ9+BY9+BZ9+CH9+CI9+CQ9+CR9+DA9+DB9+DJ9+DK9+DS9+DT9 -> 23.5 | EA9: =S9+AB9+AN9+AW9+BF9+BO9+BX9+CG9+CP9+CZ9+DI9+DR9 -> 7.5 | EB9: =J9+U9-S9+AD9-AB9+AP9-AN9+AY9-AW9+BH9-BF9+BQ9-BO9+BZ9-BX9+CI9-CG9+CR9-CP9+DB9-CZ9+DK9-DI9+DT9-DR9-CU9 -> 16 | EC9: =T9+AC9+AO9+BG9+BP9+BY9+CH9+CQ9+DA9+DA9+DJ9+DS9 -> 0 | ED9: =P9+Y9+AK9+AT9+BC9+BL9+BU9+CD9+CM9+CW9+DF9+DO9 -> 31.5 | EE9: =Q9+Z9+AL9+AU9+BD9+BM9+BV9+CE9+CN9+CX9+DG9+DP9 -> 0.5 | EF9: =R9+AA9+AM9+AV9+BE9+BN9+BW9+CF9+CO9+CY9+DH9+DQ9 -> 0 | EG9: =V9+AE9+AQ9+AZ9+BI9+BR9+CA9+CJ9+CS9+DC9+DL9+DU9 -> 0
A10: =ROW()-2 -> 8 | B10: 周子蛟 | C10: 上海 | D10: 业务一部 | E10: 商务组 | F10: 商务BD | G10: 44256 | H10: 45292 | I10: 45658 | J10: 0 | K10: =ROUND((I10-H10)/365*5,0) -> 5 | L10: 5 | M10: =K10-L10 -> 0 | Y10: 2.5 | AG10: =O10+X10 -> 0 | AH10: =M10-AG10 -> 0 | AI10: =IF(AH10<0,AH10,0) -> 0 | AK10: 8 | AS10: 2 | AT10: 3 | AU10: 1.5 | BB10: 1.5 | BD10: 2 | BE10: 8 | BK10: 1 | BL10: 11 | BT10: 0.5 | BU10: 9.5 | CD10: 2.5 | CE10: 2 | CI10: 12.5 | CM10: 1 | CN10: 1 | CP10: 9.5 | CR10: 5.5 | CZ10: 0.5 | DG10: 2 | DI10: 10.5 | DK10: 6 | DR10: 6.5 | DT10: 11.5 | DW10: =ROUND((TODAY()-I10)/365*5,2) -> 5.05 | DX10: =-AI10+AJ10+AS10+BB10+BK10+BT10+CC10+CL10+CV10+DE10+DN10 -> 5 | DY10: =DW10-DX10 -> 0.05 | DZ10: =T10+U10+AC10+AD10+AO10+AP10+AX10+AY10++BG10+BH10+BP10+BQ10+BY10+BZ10+CH10+CI10+CQ10+CR10+DA10+DB10+DJ10+DK10+DS10+DT10 -> 35.5 | EA10: =S10+AB10+AN10+AW10+BF10+BO10+BX10+CG10+CP10+CZ10+DI10+DR10 -> 27 | EB10: =J10+U10-S10+AD10-AB10+AP10-AN10+AY10-AW10+BH10-BF10+BQ10-BO10+BZ10-BX10+CI10-CG10+CR10-CP10+DB10-CZ10+DK10-DI10+DT10-DR10-CU10 -> 8.5 | EC10: =T10+AC10+AO10+BG10+BP10+BY10+CH10+CQ10+DA10+DA10+DJ10+DS10 -> 0 | ED10: =P10+Y10+AK10+AT10+BC10+BL10+BU10+CD10+CM10+CW10+DF10+DO10 -> 37.5 | EE10: =Q10+Z10+AL10+AU10+BD10+BM10+BV10+CE10+CN10+CX10+DG10+DP10 -> 8.5 | EF10: =R10+AA10+AM10+AV10+BE10+BN10+BW10+CF10+CO10+CY10+DH10+DQ10 -> 8 | EG10: =V10+AE10+AQ10+AZ10+BI10+BR10+CA10+CJ10+CS10+DC10+DL10+DU10 -> 0
A11: =ROW()-2 -> 9 | B11: 胡惜文 | C11: 上海 | D11: 业务一部 | E11: / | F11: 业务一部经理 | G11: 43647 | H11: 45292 | I11: 45658 | J11: 17.42 | K11: =ROUND((I11-H11)/365*5,0) -> 5 | L11: 5 | M11: =K11-L11 -> 0 | O11: 2 | S11: 10.5 | T11: 5 | AB11: 3 | AG11: =O11+X11 -> 2 | AH11: =M11-AG11 -> -2 | AI11: =IF(AH11<0,AH11,0) -> -2 | AJ11: 1 | AN11: 0.5 | AZ11: 2 | BB11: 1 | BH11: 16 | BQ11: 16 | CG11: 1.5 | CL11: 1 | CS11: 2 | DB11: 5.5 | DE11: 1 | DK11: 2 | DW11: =ROUND((TODAY()-I11)/365*5,2)+2.5 -> 7.55 | DX11: =-AI11+AJ11+AS11+BB11+BK11+BT11+CC11+CL11+CV11+DE11+DN11 -> 6 | DY11: =DW11-DX11 -> 1.55 | DZ11: =T11+U11+AC11+AD11+AO11+AP11+AX11+AY11++BG11+BH11+BP11+BQ11+BY11+BZ11+CH11+CI11+CQ11+CR11+DA11+DB11+DJ11+DK11+DS11+DT11 -> 44.5 | EA11: =S11+AB11+AN11+AW11+BF11+BO11+BX11+CG11+CP11+CZ11+DI11+DR11 -> 15.5 | EB11: =J11+U11-S11+AD11-AB11+AP11-AN11+AY11-AW11+BH11-BF11+BQ11-BO11+BZ11-BX11+CI11-CG11+CR11-CP11+DB11-CZ11+DK11-DI11+DT11-DR11-CU11 -> 41.42 | EC11: =T11+AC11+AO11+BG11+BP11+BY11+CH11+CQ11+DA11+DA11+DJ11+DS11 -> 5 | ED11: =P11+Y11+AK11+AT11+BC11+BL11+BU11+CD11+CM11+CW11+DF11+DO11 -> 0 | EE11: =Q11+Z11+AL11+AU11+BD11+BM11+BV11+CE11+CN11+CX11+DG11+DP11 -> 0 | EF11: =R11+AA11+AM11+AV11+BE11+BN11+BW11+CF11+CO11+CY11+DH11+DQ11 -> 0 | EG11: =V11+AE11+AQ11+AZ11+BI11+BR11+CA11+CJ11+CS11+DC11+DL11+DU11 -> 4
A12: =ROW()-2 -> 10 | B12: 何尚杰 | C12: 上海 | D12: 业务一部 | E12: 市场渠道组 | F12: 业务主管 | G12: 43270 | H12: 45292 | I12: 45658 | J12: 5 | K12: =ROUND((I12-H12)/365*5,0) -> 5 | L12: 5 | M12: =K12-L12 -> 0 | O12: 2.5 | P12: 16 | S12: 1 | X12: 0.5 | Y12: 5 | AG12: =O12+X12 -> 3 | AH12: =M12-AG12 -> -3 | AI12: =IF(AH12<0,AH12,0) -> -3 | AN12: 8 | AP12: 8 | AW12: 2.5 | AY12: 32 | BF12: 10.5 | BH12: 15 | BM12: 1.5 | BO12: 28 | BQ12: 28 | BX12: 34 | CC12: 1 | CG12: 4 | CM12: 12 | CN12: 0.5 | CR12: 8 | DB12: 16 | DI12: 12 | DK12: 8 | DR12: 17.5 | DW12: =ROUND((TODAY()-I12)/365*5,2) -> 5.05 | DX12: =-AI12+AJ12+AS12+BB12+BK12+BT12+CC12+CL12+CV12+DE12+DN12 -> 4 | DY12: =DW12-DX12 -> 1.05 | DZ12: =T12+U12+AC12+AD12+AO12+AP12+AX12+AY12++BG12+BH12+BP12+BQ12+BY12+BZ12+CH12+CI12+CQ12+CR12+DA12+DB12+DJ12+DK12+DS12+DT12 -> 115 | EA12: =S12+AB12+AN12+AW12+BF12+BO12+BX12+CG12+CP12+CZ12+DI12+DR12 -> 117.5 | EB12: =J12+U12-S12+AD12-AB12+AP12-AN12+AY12-AW12+BH12-BF12+BQ12-BO12+BZ12-BX12+CI12-CG12+CR12-CP12+DB12-CZ12+DK12-DI12+DT12-DR12-CU12 -> 2.5 | EC12: =T12+AC12+AO12+BG12+BP12+BY12+CH12+CQ12+DA12+DA12+DJ12+DS12 -> 0 | ED12: =P12+Y12+AK12+AT12+BC12+BL12+BU12+CD12+CM12+CW12+DF12+DO12 -> 33 | EE12: =Q12+Z12+AL12+AU12+BD12+BM12+BV12+CE12+CN12+CX12+DG12+DP12 -> 2 | EF12: =R12+AA12+AM12+AV12+BE12+BN12+BW12+CF12+CO12+CY12+DH12+DQ12 -> 0 | EG12: =V12+AE12+AQ12+AZ12+BI12+BR12+CA12+CJ12+CS12+DC12+DL12+DU12 -> 0
A13: =ROW()-2 -> 11 | B13: 饶洁 | C13: 上海 | D13: 业务一部 | E13: 业务运营组 | F13: 业务主管 | G13: 43696 | H13: 45292 | I13: 45658 | J13: 0 | K13: =ROUND((I13-H13)/365*5,0) -> 5 | L13: 5 | M13: =K13-L13 -> 0 | O13: 2 | Q13: 2.5 | X13: 2 | AG13: =O13+X13 -> 4 | AH13: =M13-AG13 -> -4 | AI13: =IF(AH13<0,AH13,0) -> -4 | AJ13: 1 | BH13: 13.5 | CE13: 0.5 | CG13: 4 | CL13: 4 | CP13: 5.5 | DW13: =ROUND((TODAY()-I13)/365*5,2)*2 -> 10.1 | DX13: =-AI13+AJ13+AS13+BB13+BK13+BT13+CC13+CL13+CV13+DE13+DN13 -> 9 | DY13: =DW13-DX13 -> 1.1 | DZ13: =T13+U13+AC13+AD13+AO13+AP13+AX13+AY13++BG13+BH13+BP13+BQ13+BY13+BZ13+CH13+CI13+CQ13+CR13+DA13+DB13+DJ13+DK13+DS13+DT13 -> 13.5 | EA13: =S13+AB13+AN13+AW13+BF13+BO13+BX13+CG13+CP13+CZ13+DI13+DR13 -> 9.5 | EB13: =J13+U13-S13+AD13-AB13+AP13-AN13+AY13-AW13+BH13-BF13+BQ13-BO13+BZ13-BX13+CI13-CG13+CR13-CP13+DB13-CZ13+DK13-DI13+DT13-DR13-CU13 -> 4 | EC13: =T13+AC13+AO13+BG13+BP13+BY13+CH13+CQ13+DA13+DA13+DJ13+DS13 -> 0 | ED13: =P13+Y13+AK13+AT13+BC13+BL13+BU13+CD13+CM13+CW13+DF13+DO13 -> 0 | EE13: =Q13+Z13+AL13+AU13+BD13+BM13+BV13+CE13+CN13+CX13+DG13+DP13 -> 3 | EF13: =R13+AA13+AM13+AV13+BE13+BN13+BW13+CF13+CO13+CY13+DH13+DQ13 -> 0 | EG13: =V13+AE13+AQ13+AZ13+BI13+BR13+CA13+CJ13+CS13+DC13+DL13+DU13 -> 0
A14: =ROW()-2 -> 12 | B14: 黄佳慧 | C14: 上海 | D14: 业务一部 | E14: 新媒体组 | F14: 培训讲师 | G14: 43612 | H14: 45292 | I14: 45658 | J14: 1 | K14: =ROUND((I14-H14)/365*5,0) -> 5 | L14: 5 | M14: =K14-L14 -> 0 | O14: 2 | Q14: 2 | X14: 0.5 | Z14: 1 | AB14: 1 | AG14: =O14+X14 -> 2.5 | AH14: =M14-AG14 -> -2.5 | AI14: =IF(AH14<0,AH14,0) -> -2.5 | AS14: 1 | AT14: 1 | AU14: 1 | BF14: 8 | BH14: 8 | CL14: 1 | CM14: 1 | CV14: 0.5 | CW14: 4 | DF14: 2.5 | DO14: 8 | DW14: =ROUND((TODAY()-I14)/365*5,2) -> 5.05 | DX14: =-AI14+AJ14+AS14+BB14+BK14+BT14+CC14+CL14+CV14+DE14+DN14 -> 5 | DY14: =DW14-DX14 -> 0.05 | DZ14: =T14+U14+AC14+AD14+AO14+AP14+AX14+AY14++BG14+BH14+BP14+BQ14+BY14+BZ14+CH14+CI14+CQ14+CR14+DA14+DB14+DJ14+DK14+DS14+DT14 -> 8 | EA14: =S14+AB14+AN14+AW14+BF14+BO14+BX14+CG14+CP14+CZ14+DI14+DR14 -> 9 | EB14: =J14+U14-S14+AD14-AB14+AP14-AN14+AY14-AW14+BH14-BF14+BQ14-BO14+BZ14-BX14+CI14-CG14+CR14-CP14+DB14-CZ14+DK14-DI14+DT14-DR14-CU14 -> 0 | EC14: =T14+AC14+AO14+BG14+BP14+BY14+CH14+CQ14+DA14+DA14+DJ14+DS14 -> 0 | ED14: =P14+Y14+AK14+AT14+BC14+BL14+BU14+CD14+CM14+CW14+DF14+DO14 -> 16.5 | EE14: =Q14+Z14+AL14+AU14+BD14+BM14+BV14+CE14+CN14+CX14+DG14+DP14 -> 4 | EF14: =R14+AA14+AM14+AV14+BE14+BN14+BW14+CF14+CO14+CY14+DH14+DQ14 -> 0 | EG14: =V14+AE14+AQ14+AZ14+BI14+BR14+CA14+CJ14+CS14+DC14+DL14+DU14 -> 0
A15: =ROW()-2 -> 13 | B15: 刘鑫 | C15: 上海 | D15: 业务一部 | E15: 新媒体组 | F15: 新媒体主管 | G15: 44159 | H15: 45292 | I15: 45658 | J15: 8 | K15: =ROUND((I15-H15)/365*5,0) -> 5 | L15: 5 | M15: =K15-L15 -> 0 | O15: 0.5 | S15: 1 | AG15: =O15+X15 -> 0.5 | AH15: =M15-AG15 -> -0.5 | AI15: =IF(AH15<0,AH15,0) -> -0.5 | AJ15: 1 | AN15: 1 | AS15: 0.5 | BB15: 1.5 | BF15: 1 | BH15: 8 | BT15: 3 | CC15: 1 | CG15: 1 | CP15: 1 | CR15: 8 | DN15: 0.5 | DW15: =ROUND((TODAY()-I15)/365*5,2)*2 -> 10.1 | DX15: =-AI15+AJ15+AS15+BB15+BK15+BT15+CC15+CL15+CV15+DE15+DN15 -> 8 | DY15: =DW15-DX15 -> 2.1 | DZ15: =T15+U15+AC15+AD15+AO15+AP15+AX15+AY15++BG15+BH15+BP15+BQ15+BY15+BZ15+CH15+CI15+CQ15+CR15+DA15+DB15+DJ15+DK15+DS15+DT15 -> 16 | EA15: =S15+AB15+AN15+AW15+BF15+BO15+BX15+CG15+CP15+CZ15+DI15+DR15 -> 5 | EB15: =J15+U15-S15+AD15-AB15+AP15-AN15+AY15-AW15+BH15-BF15+BQ15-BO15+BZ15-BX15+CI15-CG15+CR15-CP15+DB15-CZ15+DK15-DI15+DT15-DR15-CU15 -> 19 | EC15: =T15+AC15+AO15+BG15+BP15+BY15+CH15+CQ15+DA15+DA15+DJ15+DS15 -> 0 | ED15: =P15+Y15+AK15+AT15+BC15+BL15+BU15+CD15+CM15+CW15+DF15+DO15 -> 0 | EE15: =Q15+Z15+AL15+AU15+BD15+BM15+BV15+CE15+CN15+CX15+DG15+DP15 -> 0 | EF15: =R15+AA15+AM15+AV15+BE15+BN15+BW15+CF15+CO15+CY15+DH15+DQ15 -> 0 | EG15: =V15+AE15+AQ15+AZ15+BI15+BR15+CA15+CJ15+CS15+DC15+DL15+DU15 -> 0
A16: =ROW()-2 -> 14 | B16: 屈翎野 | C16: 上海 | D16: 业务一部 | E16: 新媒体组 | F16: 新媒体专员 | G16: 43185 | H16: 45292 | I16: 45658 | J16: 28 | K16: =ROUND((I16-H16)/365*5,0) -> 5 | L16: 4 | M16: =K16-L16 -> 1 | O16: 1 | S16: 0.5 | X16: 1 | AG16: =O16+X16 -> 2 | AH16: =M16-AG16 -> -1 | AI16: =IF(AH16<0,AH16,0) -> -1 | AW16: 9 | BF16: 1 | BK16: 1 | BX16: 1 | CL16: 3 | CV16: 0.5 | DI16: 2 | DN16: 1 | DR16: 3 | DW16: =ROUND((TODAY()-I16)/365*5,2)*2 -> 10.1 | DX16: =-AI16+AJ16+AS16+BB16+BK16+BT16+CC16+CL16+CV16+DE16+DN16 -> 6.5 | DY16: =DW16-DX16 -> 3.6 | DZ16: =T16+U16+AC16+AD16+AO16+AP16+AX16+AY16++BG16+BH16+BP16+BQ16+BY16+BZ16+CH16+CI16+CQ16+CR16+DA16+DB16+DJ16+DK16+DS16+DT16 -> 0 | EA16: =S16+AB16+AN16+AW16+BF16+BO16+BX16+CG16+CP16+CZ16+DI16+DR16 -> 16.5 | EB16: =J16+U16-S16+AD16-AB16+AP16-AN16+AY16-AW16+BH16-BF16+BQ16-BO16+BZ16-BX16+CI16-CG16+CR16-CP16+DB16-CZ16+DK16-DI16+DT16-DR16-CU16 -> 11.5 | EC16: =T16+AC16+AO16+BG16+BP16+BY16+CH16+CQ16+DA16+DA16+DJ16+DS16 -> 0 | ED16: =P16+Y16+AK16+AT16+BC16+BL16+BU16+CD16+CM16+CW16+DF16+DO16 -> 0 | EE16: =Q16+Z16+AL16+AU16+BD16+BM16+BV16+CE16+CN16+CX16+DG16+DP16 -> 0 | EF16: =R16+AA16+AM16+AV16+BE16+BN16+BW16+CF16+CO16+CY16+DH16+DQ16 -> 0 | EG16: =V16+AE16+AQ16+AZ16+BI16+BR16+CA16+CJ16+CS16+DC16+DL16+DU16 -> 0
A17: =ROW()-2 -> 15 | B17: 陆常斌 | C17: 上海 | D17: 业务一部 | E17: 新媒体组 | F17: 视频剪辑 | G17: 44991 | H17: 45292 | I17: 45658 | J17: 0 | K17: =ROUND((I17-H17)/365*5,0) -> 5 | L17: 5 | M17: =K17-L17 -> 0 | O17: 2 | AG17: =O17+X17 -> 2 | AH17: =M17-AG17 -> -2 | AI17: =IF(AH17<0,AH17,0) -> -2 | AN17: 16 | AP17: 16 | BB17: 2 | CR17: 4 | DK17: 4 | DN17: 1 | DT17: 40 | DW17: =ROUND((TODAY()-I17)/365*5,2) -> 5.05 | DX17: =-AI17+AJ17+AS17+BB17+BK17+BT17+CC17+CL17+CV17+DE17+DN17 -> 5 | DY17: =DW17-DX17 -> 0.05 | DZ17: =T17+U17+AC17+AD17+AO17+AP17+AX17+AY17++BG17+BH17+BP17+BQ17+BY17+BZ17+CH17+CI17+CQ17+CR17+DA17+DB17+DJ17+DK17+DS17+DT17 -> 64 | EA17: =S17+AB17+AN17+AW17+BF17+BO17+BX17+CG17+CP17+CZ17+DI17+DR17 -> 16 | EB17: =J17+U17-S17+AD17-AB17+AP17-AN17+AY17-AW17+BH17-BF17+BQ17-BO17+BZ17-BX17+CI17-CG17+CR17-CP17+DB17-CZ17+DK17-DI17+DT17-DR17-CU17 -> 48 | EC17: =T17+AC17+AO17+BG17+BP17+BY17+CH17+CQ17+DA17+DA17+DJ17+DS17 -> 0 | ED17: =P17+Y17+AK17+AT17+BC17+BL17+BU17+CD17+CM17+CW17+DF17+DO17 -> 0 | EE17: =Q17+Z17+AL17+AU17+BD17+BM17+BV17+CE17+CN17+CX17+DG17+DP17 -> 0 | EF17: =R17+AA17+AM17+AV17+BE17+BN17+BW17+CF17+CO17+CY17+DH17+DQ17 -> 0 | EG17: =V17+AE17+AQ17+AZ17+BI17+BR17+CA17+CJ17+CS17+DC17+DL17+DU17 -> 0
A18: =ROW()-2 -> 16 | B18: 孙玉凤 | C18: 上海 | D18: 人力资源部 | E18: / | F18: 人力资源总监 | G18: 43192 | H18: 45292 | I18: 45658 | J18: 66.5 | K18: =ROUND((I18-H18)/365*5,0)*2 -> 10 | L18: 5 | M18: =K18-L18 -> 5 | O18: 2.5 | U18: 10.5 | AB18: 15 | AC18: 15 | AD18: 6 | AG18: =O18+X18 -> 2.5 | AH18: =M18-AG18 -> 2.5 | AI18: =IF(AH18<0,AH18,0) -> 0 | AJ18: 1.5 | AL18: 1 | AP18: 11 | AS18: 1 | AU18: 0.5 | AW18: 5.5 | AY18: 12 | BB18: 0.5 | BH18: 8 | BJ18: 15 | BK18: 0.5 | BM18: 1 | BQ18: 5.5 | BT18: 1 | BZ18: 11.5 | CC18: 0.5 | CE18: 1 | CI18: 6 | CL18: 1 | CR18: 19 | CU18: 77.5 | CV18: 2 | DB18: 8 | DE18: 1 | DK18: 8 | DN18: 1 | DT18: 21 | DW18: =ROUND((TODAY()-I18)/365*5,2)*2 -> 10.1 | DX18: =-AI18+AJ18+AS18+BB18+BK18+BT18+CC18+CL18+CV18+DE18+DN18 -> 10 | DY18: =DW18-DX18 -> 0.1 | DZ18: =T18+U18+AC18+AD18+AO18+AP18+AX18+AY18++BG18+BH18+BP18+BQ18+BY18+BZ18+CH18+CI18+CQ18+CR18+DA18+DB18+DJ18+DK18+DS18+DT18 -> 141.5 | EA18: =S18+AB18+AN18+AW18+BF18+BO18+BX18+CG18+CP18+CZ18+DI18+DR18 -> 20.5 | EB18: =J18+U18-S18+AD18-AB18+AP18-AN18+AY18-AW18+BH18-BF18+BQ18-BO18+BZ18-BX18+CI18-CG18+CR18-CP18+DB18-CZ18+DK18-DI18+DT18-DR18-CU18 -> 95 | EC18: =T18+AC18+AO18+BG18+BP18+BY18+CH18+CQ18+DA18+DA18+DJ18+DS18 -> 15 | ED18: =P18+Y18+AK18+AT18+BC18+BL18+BU18+CD18+CM18+CW18+DF18+DO18 -> 0 | EE18: =Q18+Z18+AL18+AU18+BD18+BM18+BV18+CE18+CN18+CX18+DG18+DP18 -> 3.5 | EF18: =R18+AA18+AM18+AV18+BE18+BN18+BW18+CF18+CO18+CY18+DH18+DQ18 -> 0 | EG18: =V18+AE18+AQ18+AZ18+BI18+BR18+CA18+CJ18+CS18+DC18+DL18+DU18 -> 0
A19: =ROW()-2 -> 17 | B19: 纪志豪 | C19: 上海 | D19: 人力资源部 | E19: / | F19: 资深人事 | G19: 43947 | H19: 45292 | I19: 45658 | J19: 44 | K19: =ROUND((I19-H19)/365*5,0) -> 5 | L19: 5 | M19: =K19-L19 -> 0 | S19: 4 | U19: 25 | AB19: 6.5 | AD19: 5.5 | AG19: =O19+X19 -> 0 | AH19: =M19-AG19 -> 0 | AI19: =IF(AH19<0,AH19,0) -> 0 | AJ19: 4 | AL19: 0.5 | AN19: 9.5 | AP19: 23.5 | AS19: 1 | AV19: 1 | AW19: 6.5 | AY19: 6 | AZ19: 1 | BE19: 8 | BF19: 8.5 | BI19: 0.5 | BO19: 19 | BQ19: 13 | BR19: 0.5 | BV19: 1.5 | BX19: 9 | BZ19: 4 | CG19: 4 | CI19: 13.5 | CR19: 7 | CS19: 3 | CZ19: 12 | DB19: 11.5 | DI19: 4 | DK19: 9.5 | DR19: 10 | DT19: 23 | DW19: =ROUND((TODAY()-I19)/365*5,2) -> 5.05 | DX19: =-AI19+AJ19+AS19+BB19+BK19+BT19+CC19+CL19+CV19+DE19+DN19 -> 5 | DY19: =DW19-DX19 -> 0.05 | DZ19: =T19+U19+AC19+AD19+AO19+AP19+AX19+AY19++BG19+BH19+BP19+BQ19+BY19+BZ19+CH19+CI19+CQ19+CR19+DA19+DB19+DJ19+DK19+DS19+DT19 -> 141.5 | EA19: =S19+AB19+AN19+AW19+BF19+BO19+BX19+CG19+CP19+CZ19+DI19+DR19 -> 93 | EB19: =J19+U19-S19+AD19-AB19+AP19-AN19+AY19-AW19+BH19-BF19+BQ19-BO19+BZ19-BX19+CI19-CG19+CR19-CP19+DB19-CZ19+DK19-DI19+DT19-DR19-CU19 -> 92.5 | EC19: =T19+AC19+AO19+BG19+BP19+BY19+CH19+CQ19+DA19+DA19+DJ19+DS19 -> 0 | ED19: =P19+Y19+AK19+AT19+BC19+BL19+BU19+CD19+CM19+CW19+DF19+DO19 -> 0 | EE19: =Q19+Z19+AL19+AU19+BD19+BM19+BV19+CE19+CN19+CX19+DG19+DP19 -> 2 | EF19: =R19+AA19+AM19+AV19+BE19+BN19+BW19+CF19+CO19+CY19+DH19+DQ19 -> 9 | EG19: =V19+AE19+AQ19+AZ19+BI19+BR19+CA19+CJ19+CS19+DC19+DL19+DU19 -> 5
A20: =ROW()-2 -> 18 | B20: 熊溜溜 | C20: 上海 | D20: 人力资源部 | E20: / | F20: 资深人事 | G20: 44088 | H20: 45292 | I20: 45658 | J20: 0 | K20: =ROUND((I20-H20)/365*5,0) -> 5 | L20: 5 | M20: =K20-L20 -> 0 | Y20: 152 | AG20: =O20+X20 -> 0 | AH20: =M20-AG20 -> 0 | AI20: =IF(AH20<0,AH20,0) -> 0 | AP20: 8 | AV20: 28 | AY20: 5.5 | BH20: 8 | BN20: 38 | BQ20: 7 | CI20: 7.5 | CJ20: 2 | CR20: 7.5 | CS20: 3 | CZ20: 1.5 | DB20: 5 | DE20: 2 | DK20: 19 | DN20: 2 | DR20: 0.5 | DT20: 14 | DW20: =ROUND((TODAY()-I20)/365*5,2) -> 5.05 | DX20: =-AI20+AJ20+AS20+BB20+BK20+BT20+CC20+CL20+CV20+DE20+DN20 -> 4 | DY20: =DW20-DX20 -> 1.05 | DZ20: =T20+U20+AC20+AD20+AO20+AP20+AX20+AY20++BG20+BH20+BP20+BQ20+BY20+BZ20+CH20+CI20+CQ20+CR20+DA20+DB20+DJ20+DK20+DS20+DT20 -> 81.5 | EA20: =S20+AB20+AN20+AW20+BF20+BO20+BX20+CG20+CP20+CZ20+DI20+DR20 -> 2 | EB20: =J20+U20-S20+AD20-AB20+AP20-AN20+AY20-AW20+BH20-BF20+BQ20-BO20+BZ20-BX20+CI20-CG20+CR20-CP20+DB20-CZ20+DK20-DI20+DT20-DR20-CU20 -> 79.5 | EC20: =T20+AC20+AO20+BG20+BP20+BY20+CH20+CQ20+DA20+DA20+DJ20+DS20 -> 0 | ED20: =P20+Y20+AK20+AT20+BC20+BL20+BU20+CD20+CM20+CW20+DF20+DO20 -> 152 | EE20: =Q20+Z20+AL20+AU20+BD20+BM20+BV20+CE20+CN20+CX20+DG20+DP20 -> 0 | EF20: =R20+AA20+AM20+AV20+BE20+BN20+BW20+CF20+CO20+CY20+DH20+DQ20 -> 66 | EG20: =V20+AE20+AQ20+AZ20+BI20+BR20+CA20+CJ20+CS20+DC20+DL20+DU20 -> 5
A21: =ROW()-2 -> 19 | B21: 郭昱伶 | C21: 上海 | D21: 人力资源部 | E21: / | F21: 资深人事 | G21: 44322 | H21: 45292 | I21: 45658 | J21: 0 | K21: =ROUND((I21-H21)/365*5,0) -> 5 | L21: 5 | M21: =K21-L21 -> 0 | O21: 5 | P21: 8 | Y21: 8 | AG21: =O21+X21 -> 5 | AH21: =M21-AG21 -> -5 | AI21: =IF(AH21<0,AH21,0) -> -5 | AP21: 17 | AT21: 5 | AW21: 13.5 | BF21: 2.5 | BM21: 1 | BQ21: 5 | BV21: 1 | BX21: 4 | CD21: 16 | CE21: 0.5 | CG21: 1 | CN21: 1 | CR21: 2 | CZ21: 1.5 | DI21: 1.5 | DN21: 0.5 | DO21: 3.5 | DS21: 16 | DT21: 5.5 | DW21: =ROUND((TODAY()-I21)/365*5,2)+1.5 -> 6.55 | DX21: =-AI21+AJ21+AS21+BB21+BK21+BT21+CC21+CL21+CV21+DE21+DN21 -> 5.5 | DY21: =DW21-DX21 -> 1.05 | DZ21: =T21+U21+AC21+AD21+AO21+AP21+AX21+AY21++BG21+BH21+BP21+BQ21+BY21+BZ21+CH21+CI21+CQ21+CR21+DA21+DB21+DJ21+DK21+DS21+DT21 -> 45.5 | EA21: =S21+AB21+AN21+AW21+BF21+BO21+BX21+CG21+CP21+CZ21+DI21+DR21 -> 24 | EB21: =J21+U21-S21+AD21-AB21+AP21-AN21+AY21-AW21+BH21-BF21+BQ21-BO21+BZ21-BX21+CI21-CG21+CR21-CP21+DB21-CZ21+DK21-DI21+DT21-DR21-CU21 -> 5.5 | EC21: =T21+AC21+AO21+BG21+BP21+BY21+CH21+CQ21+DA21+DA21+DJ21+DS21 -> 16 | ED21: =P21+Y21+AK21+AT21+BC21+BL21+BU21+CD21+CM21+CW21+DF21+DO21 -> 40.5 | EE21: =Q21+Z21+AL21+AU21+BD21+BM21+BV21+CE21+CN21+CX21+DG21+DP21 -> 3.5 | EF21: =R21+AA21+AM21+AV21+BE21+BN21+BW21+CF21+CO21+CY21+DH21+DQ21 -> 0 | EG21: =V21+AE21+AQ21+AZ21+BI21+BR21+CA21+CJ21+CS21+DC21+DL21+DU21 -> 0
A22: =ROW()-2 -> 20 | B22: 李丽萍 | C22: 上海 | D22: 人力资源部 | E22: / | F22: 人事专员 | G22: 44979 | H22: 45292 | I22: 45658 | J22: 0 | K22: =ROUND((I22-H22)/365*5,0) -> 5 | L22: 5.5 | M22: =K22-L22 -> -0.5 | O22: 5 | P22: 9.5 | R22: 1.5 | AG22: =O22+X22 -> 5 | AH22: =M22-AG22 -> -5.5 | AI22: =IF(AH22<0,AH22,0) -> -5.5 | CD22: 6.5 | CJ22: 1 | CS22: 0.5 | CW22: 4.5 | DO22: 3 | DT22: 15 | DW22: =ROUND((TODAY()-I22)/365*5,2) -> 5.05 | DX22: =-AI22+AJ22+AS22+BB22+BK22+BT22+CC22+CL22+CV22+DE22+DN22 -> 5.5 | DY22: =DW22-DX22 -> -0.45 | DZ22: =T22+U22+AC22+AD22+AO22+AP22+AX22+AY22++BG22+BH22+BP22+BQ22+BY22+BZ22+CH22+CI22+CQ22+CR22+DA22+DB22+DJ22+DK22+DS22+DT22 -> 15 | EA22: =S22+AB22+AN22+AW22+BF22+BO22+BX22+CG22+CP22+CZ22+DI22+DR22 -> 0 | EB22: =J22+U22-S22+AD22-AB22+AP22-AN22+AY22-AW22+BH22-BF22+BQ22-BO22+BZ22-BX22+CI22-CG22+CR22-CP22+DB22-CZ22+DK22-DI22+DT22-DR22-CU22 -> 15 | EC22: =T22+AC22+AO22+BG22+BP22+BY22+CH22+CQ22+DA22+DA22+DJ22+DS22 -> 0 | ED22: =P22+Y22+AK22+AT22+BC22+BL22+BU22+CD22+CM22+CW22+DF22+DO22 -> 23.5 | EE22: =Q22+Z22+AL22+AU22+BD22+BM22+BV22+CE22+CN22+CX22+DG22+DP22 -> 0 | EF22: =R22+AA22+AM22+AV22+BE22+BN22+BW22+CF22+CO22+CY22+DH22+DQ22 -> 1.5 | EG22: =V22+AE22+AQ22+AZ22+BI22+BR22+CA22+CJ22+CS22+DC22+DL22+DU22 -> 1.5
A23: =ROW()-2 -> 21 | B23: 郭洁 | C23: 上海 | D23: 产研二部 | E23: 产品部 | F23: 产品部经理 | G23: 43045 | H23: 45292 | I23: 45658 | J23: 4 | K23: =ROUND((I23-H23)/365*5,0) -> 5 | L23: 4.5 | M23: =K23-L23 -> 0.5 | O23: 1 | S23: 2 | X23: 0.5 | AB23: 8 | AD23: 6 | AG23: =O23+X23 -> 1.5 | AH23: =M23-AG23 -> -1 | AI23: =IF(AH23<0,AH23,0) -> -1 | AK23: 3 | AL23: 9 | AP23: 7 | AS23: 1 | AW23: 7 | AY23: 4 | BB23: 2 | BC23: 0.5 | BH23: 4 | BL23: 2.5 | BO23: 2.5 | BP23: 4.5 | BX23: 5.5 | BY23: 14.5 | CD23: 1 | CE23: 1 | CH23: 6 | CL23: 0.5 | CM23: 0 | CQ23: 2.5 | CW23: 6.5 | DK23: 4 | DO23: 24 | DR23: 2.5 | DW23: =ROUND((TODAY()-I23)/365*5,2) -> 5.05 | DX23: =-AI23+AJ23+AS23+BB23+BK23+BT23+CC23+CL23+CV23+DE23+DN23 -> 4.5 | DY23: =DW23-DX23 -> 0.55 | DZ23: =T23+U23+AC23+AD23+AO23+AP23+AX23+AY23++BG23+BH23+BP23+BQ23+BY23+BZ23+CH23+CI23+CQ23+CR23+DA23+DB23+DJ23+DK23+DS23+DT23 -> 52.5 | EA23: =S23+AB23+AN23+AW23+BF23+BO23+BX23+CG23+CP23+CZ23+DI23+DR23 -> 27.5 | EB23: =J23+U23-S23+AD23-AB23+AP23-AN23+AY23-AW23+BH23-BF23+BQ23-BO23+BZ23-BX23+CI23-CG23+CR23-CP23+DB23-CZ23+DK23-DI23+DT23-DR23-CU23 -> 1.5 | EC23: =T23+AC23+AO23+BG23+BP23+BY23+CH23+CQ23+DA23+DA23+DJ23+DS23 -> 27.5 | ED23: =P23+Y23+AK23+AT23+BC23+BL23+BU23+CD23+CM23+CW23+DF23+DO23 -> 37.5 | EE23: =Q23+Z23+AL23+AU23+BD23+BM23+BV23+CE23+CN23+CX23+DG23+DP23 -> 10 | EF23: =R23+AA23+AM23+AV23+BE23+BN23+BW23+CF23+CO23+CY23+DH23+DQ23 -> 0 | EG23: =V23+AE23+AQ23+AZ23+BI23+BR23+CA23+CJ23+CS23+DC23+DL23+DU23 -> 0
A24: =ROW()-2 -> 22 | B24: 毛意伟 | C24: 上海 | D24: 产研二部 | E24: 业务管理一组 | F24: 研发主管（PHP） | G24: 43243 | H24: 45292 | I24: 45658 | J24: 25.5 | K24: =ROUND((I24-H24)/365*5,0) -> 5 | L24: 5 | M24: =K24-L24 -> 0 | S24: 16.5 | AA24: 10 | AB24: 5 | AG24: =O24+X24 -> 0 | AH24: =M24-AG24 -> 0 | AI24: =IF(AH24<0,AH24,0) -> 0 | AJ24: 0.5 | AN24: 4 | AP24: 16 | AS24: 3.5 | AY24: 8 | BF24: 5.5 | BH24: 4 | BO24: 8.5 | BX24: 12 | BZ24: 8 | CG24: 14 | CI24: 8 | CL24: 1 | CO24: 8 | CP24: 3 | CZ24: 9 | DB24: 8 | DC24: 0.5 | DI24: 1 | DK24: 8 | DR24: 3 | DT24: 8 | DU24: 0.5 | DW24: =ROUND((TODAY()-I24)/365*5,2) -> 5.05 | DX24: =-AI24+AJ24+AS24+BB24+BK24+BT24+CC24+CL24+CV24+DE24+DN24 -> 5 | DY24: =DW24-DX24 -> 0.05 | DZ24: =T24+U24+AC24+AD24+AO24+AP24+AX24+AY24++BG24+BH24+BP24+BQ24+BY24+BZ24+CH24+CI24+CQ24+CR24+DA24+DB24+DJ24+DK24+DS24+DT24 -> 68 | EA24: =S24+AB24+AN24+AW24+BF24+BO24+BX24+CG24+CP24+CZ24+DI24+DR24 -> 81.5 | EB24: =J24+U24-S24+AD24-AB24+AP24-AN24+AY24-AW24+BH24-BF24+BQ24-BO24+BZ24-BX24+CI24-CG24+CR24-CP24+DB24-CZ24+DK24-DI24+DT24-DR24-CU24 -> 12 | EC24: =T24+AC24+AO24+BG24+BP24+BY24+CH24+CQ24+DA24+DA24+DJ24+DS24 -> 0 | ED24: =P24+Y24+AK24+AT24+BC24+BL24+BU24+CD24+CM24+CW24+DF24+DO24 -> 0 | EE24: =Q24+Z24+AL24+AU24+BD24+BM24+BV24+CE24+CN24+CX24+DG24+DP24 -> 0 | EF24: =R24+AA24+AM24+AV24+BE24+BN24+BW24+CF24+CO24+CY24+DH24+DQ24 -> 18 | EG24: =V24+AE24+AQ24+AZ24+BI24+BR24+CA24+CJ24+CS24+DC24+DL24+DU24 -> 1
A25: =ROW()-2 -> 23 | B25: 彭鲲 | C25: 上海 | D25: 产研一部 | E25: 教育一组 | F25: 产品经理 | G25: 44270 | H25: 45292 | I25: 45658 | J25: 0 | K25: =ROUND((I25-H25)/365*5,0) -> 5 | L25: 5 | M25: =K25-L25 -> 0 | U25: 16 | AB25: 10 | AG25: =O25+X25 -> 0 | AH25: =M25-AG25 -> 0 | AI25: =IF(AH25<0,AH25,0) -> 0 | AK25: 2 | AN25: 6 | AO25: 8 | AS25: 1 | BB25: 0.5 | BK25: 1.5 | BL25: 1 | BU25: 3 | CD25: 1 | CH25: 16 | CQ25: 8 | CV25: 1 | DJ25: 15.5 | DS25: 16 | DW25: =ROUND((TODAY()-I25)/365*5,2) -> 5.05 | DX25: =-AI25+AJ25+AS25+BB25+BK25+BT25+CC25+CL25+CV25+DE25+DN25 -> 4 | DY25: =DW25-DX25 -> 1.05 | DZ25: =T25+U25+AC25+AD25+AO25+AP25+AX25+AY25++BG25+BH25+BP25+BQ25+BY25+BZ25+CH25+CI25+CQ25+CR25+DA25+DB25+DJ25+DK25+DS25+DT25 -> 79.5 | EA25: =S25+AB25+AN25+AW25+BF25+BO25+BX25+CG25+CP25+CZ25+DI25+DR25 -> 16 | EB25: =J25+U25-S25+AD25-AB25+AP25-AN25+AY25-AW25+BH25-BF25+BQ25-BO25+BZ25-BX25+CI25-CG25+CR25-CP25+DB25-CZ25+DK25-DI25+DT25-DR25-CU25 -> 0 | EC25: =T25+AC25+AO25+BG25+BP25+BY25+CH25+CQ25+DA25+DA25+DJ25+DS25 -> 63.5 | ED25: =P25+Y25+AK25+AT25+BC25+BL25+BU25+CD25+CM25+CW25+DF25+DO25 -> 7 | EE25: =Q25+Z25+AL25+AU25+BD25+BM25+BV25+CE25+CN25+CX25+DG25+DP25 -> 0 | EF25: =R25+AA25+AM25+AV25+BE25+BN25+BW25+CF25+CO25+CY25+DH25+DQ25 -> 0 | EG25: =V25+AE25+AQ25+AZ25+BI25+BR25+CA25+CJ25+CS25+DC25+DL25+DU25 -> 0
A26: =ROW()-2 -> 24 | B26: 王冉冉 | C26: 上海 | D26: 产研二部 | E26: 业务管理一组 | F26: 测试主管 | G26: 44333 | H26: 45292 | I26: 45658 | J26: 49 | K26: =ROUND((I26-H26)/365*5,0) -> 5 | L26: 5 | M26: =K26-L26 -> 0 | Q26: 1 | S26: 40 | U26: 5.5 | Z26: 1 | AB26: 9 | AG26: =O26+X26 -> 0 | AH26: =M26-AG26 -> 0 | AI26: =IF(AH26<0,AH26,0) -> 0 | AJ26: 1 | AK26: 4.5 | AN26: 5.5 | AP26: 14 | AV26: 3 | AW26: 21.5 | AY26: 14 | BF26: 5.5 | BH26: 13 | BK26: 2 | BO26: 8 | BQ26: 21.5 | BX26: 14 | BZ26: 6.5 | CE26: 0.5 | CI26: 11 | CP26: 7.5 | CR26: 13.5 | DB26: 7 | DK26: 14 | DR26: 8 | DT26: 7.5 | DW26: =ROUND((TODAY()-I26)/365*5,2) -> 5.05 | DX26: =-AI26+AJ26+AS26+BB26+BK26+BT26+CC26+CL26+CV26+DE26+DN26 -> 3 | DY26: =DW26-DX26 -> 2.05 | DZ26: =T26+U26+AC26+AD26+AO26+AP26+AX26+AY26++BG26+BH26+BP26+BQ26+BY26+BZ26+CH26+CI26+CQ26+CR26+DA26+DB26+DJ26+DK26+DS26+DT26 -> 127.5 | EA26: =S26+AB26+AN26+AW26+BF26+BO26+BX26+CG26+CP26+CZ26+DI26+DR26 -> 119 | EB26: =J26+U26-S26+AD26-AB26+AP26-AN26+AY26-AW26+BH26-BF26+BQ26-BO26+BZ26-BX26+CI26-CG26+CR26-CP26+DB26-CZ26+DK26-DI26+DT26-DR26-CU26 -> 57.5 | EC26: =T26+AC26+AO26+BG26+BP26+BY26+CH26+CQ26+DA26+DA26+DJ26+DS26 -> 0 | ED26: =P26+Y26+AK26+AT26+BC26+BL26+BU26+CD26+CM26+CW26+DF26+DO26 -> 4.5 | EE26: =Q26+Z26+AL26+AU26+BD26+BM26+BV26+CE26+CN26+CX26+DG26+DP26 -> 2.5 | EF26: =R26+AA26+AM26+AV26+BE26+BN26+BW26+CF26+CO26+CY26+DH26+DQ26 -> 3 | EG26: =V26+AE26+AQ26+AZ26+BI26+BR26+CA26+CJ26+CS26+DC26+DL26+DU26 -> 0
A27: =ROW()-2 -> 25 | B27: 张金凯 | C27: 上海 | D27: 产研二部 | E27: 后台二组 | F27: 测试主管 | G27: 44333 | H27: 45292 | I27: 45658 | J27: 20 | K27: =ROUND((I27-H27)/365*5,0) -> 5 | L27: 5 | M27: =K27-L27 -> 0 | O27: 4.5 | S27: 1.5 | U27: 24 | X27: 0.5 | AB27: 37.5 | AG27: =O27+X27 -> 5 | AH27: =M27-AG27 -> -5 | AI27: =IF(AH27<0,AH27,0) -> -5 | AP27: 32 | AW27: 3 | AY27: 8 | BF27: 34 | BH27: 8 | BQ27: 16 | BX27: 8 | BZ27: 12 | CG27: 4.5 | CI27: 16 | CP27: 26.5 | CR27: 9.5 | CZ27: 24 | DK27: 8 | DT27: 16 | DW27: =ROUND((TODAY()-I27)/365*5,2) -> 5.05 | DX27: =-AI27+AJ27+AS27+BB27+BK27+BT27+CC27+CL27+CV27+DE27+DN27 -> 5 | DY27: =DW27-DX27 -> 0.05 | DZ27: =T27+U27+AC27+AD27+AO27+AP27+AX27+AY27++BG27+BH27+BP27+BQ27+BY27+BZ27+CH27+CI27+CQ27+CR27+DA27+DB27+DJ27+DK27+DS27+DT27 -> 149.5 | EA27: =S27+AB27+AN27+AW27+BF27+BO27+BX27+CG27+CP27+CZ27+DI27+DR27 -> 139 | EB27: =J27+U27-S27+AD27-AB27+AP27-AN27+AY27-AW27+BH27-BF27+BQ27-BO27+BZ27-BX27+CI27-CG27+CR27-CP27+DB27-CZ27+DK27-DI27+DT27-DR27-CU27 -> 30.5 | EC27: =T27+AC27+AO27+BG27+BP27+BY27+CH27+CQ27+DA27+DA27+DJ27+DS27 -> 0 | ED27: =P27+Y27+AK27+AT27+BC27+BL27+BU27+CD27+CM27+CW27+DF27+DO27 -> 0 | EE27: =Q27+Z27+AL27+AU27+BD27+BM27+BV27+CE27+CN27+CX27+DG27+DP27 -> 0 | EF27: =R27+AA27+AM27+AV27+BE27+BN27+BW27+CF27+CO27+CY27+DH27+DQ27 -> 0 | EG27: =V27+AE27+AQ27+AZ27+BI27+BR27+CA27+CJ27+CS27+DC27+DL27+DU27 -> 0
A28: =ROW()-2 -> 26 | B28: 王晓倩 | C28: 上海 | D28: 产研二部 | E28: 业务管理一组 | F28: PHP开发工程师 | G28: 43640 | H28: 45292 | I28: 45658 | J28: 24.5 | K28: =ROUND((I28-H28)/365*5,0) -> 5 | L28: 5 | M28: =K28-L28 -> 0 | O28: 3 | S28: 4 | U28: 7.5 | X28: 2 | AB28: 8 | AG28: =O28+X28 -> 5 | AH28: =M28-AG28 -> -5 | AI28: =IF(AH28<0,AH28,0) -> -5 | AN28: 8 | AP28: 25.5 | AW28: 1 | BE28: 8 | BF28: 8 | BM28: 0.5 | BX28: 29.5 | BZ28: 13 | CG28: 16 | CI28: 8 | CM28: 26.5 | CW28: 8 | DK28: 5 | DO28: 8 | DR28: 5.5 | DW28: =ROUND((TODAY()-I28)/365*5,2) -> 5.05 | DX28: =-AI28+AJ28+AS28+BB28+BK28+BT28+CC28+CL28+CV28+DE28+DN28 -> 5 | DY28: =DW28-DX28 -> 0.05 | DZ28: =T28+U28+AC28+AD28+AO28+AP28+AX28+AY28++BG28+BH28+BP28+BQ28+BY28+BZ28+CH28+CI28+CQ28+CR28+DA28+DB28+DJ28+DK28+DS28+DT28 -> 59 | EA28: =S28+AB28+AN28+AW28+BF28+BO28+BX28+CG28+CP28+CZ28+DI28+DR28 -> 80 | EB28: =J28+U28-S28+AD28-AB28+AP28-AN28+AY28-AW28+BH28-BF28+BQ28-BO28+BZ28-BX28+CI28-CG28+CR28-CP28+DB28-CZ28+DK28-DI28+DT28-DR28-CU28 -> 3.5 | EC28: =T28+AC28+AO28+BG28+BP28+BY28+CH28+CQ28+DA28+DA28+DJ28+DS28 -> 0 | ED28: =P28+Y28+AK28+AT28+BC28+BL28+BU28+CD28+CM28+CW28+DF28+DO28 -> 42.5 | EE28: =Q28+Z28+AL28+AU28+BD28+BM28+BV28+CE28+CN28+CX28+DG28+DP28 -> 0.5 | EF28: =R28+AA28+AM28+AV28+BE28+BN28+BW28+CF28+CO28+CY28+DH28+DQ28 -> 8 | EG28: =V28+AE28+AQ28+AZ28+BI28+BR28+CA28+CJ28+CS28+DC28+DL28+DU28 -> 0
A29: =ROW()-2 -> 27 | B29: 李浩然 | C29: 上海 | D29: 产研二部 | E29: 业务管理一组 | F29: 资深前端开发工程师 | G29: 44305 | H29: 45292 | I29: 45658 | J29: 19.1 | K29: =ROUND((I29-H29)/365*5,0) -> 5 | L29: 5 | M29: =K29-L29 -> 0 | X29: 2 | AB29: 1.5 | AG29: =O29+X29 -> 2 | AH29: =M29-AG29 -> -2 | AI29: =IF(AH29<0,AH29,0) -> -2 | AJ29: 1.5 | AN29: 6.25 | AP29: 10.5 | BH29: 5.5 | BK29: 1.5 | BZ29: 16 | CI29: 6 | CP29: 13 | CZ29: 8 | DI29: 3 | DW29: =ROUND((TODAY()-I29)/365*5,2) -> 5.05 | DX29: =-AI29+AJ29+AS29+BB29+BK29+BT29+CC29+CL29+CV29+DE29+DN29 -> 5 | DY29: =DW29-DX29 -> 0.05 | DZ29: =T29+U29+AC29+AD29+AO29+AP29+AX29+AY29++BG29+BH29+BP29+BQ29+BY29+BZ29+CH29+CI29+CQ29+CR29+DA29+DB29+DJ29+DK29+DS29+DT29 -> 38 | EA29: =S29+AB29+AN29+AW29+BF29+BO29+BX29+CG29+CP29+CZ29+DI29+DR29 -> 31.75 | EB29: =J29+U29-S29+AD29-AB29+AP29-AN29+AY29-AW29+BH29-BF29+BQ29-BO29+BZ29-BX29+CI29-CG29+CR29-CP29+DB29-CZ29+DK29-DI29+DT29-DR29-CU29 -> 25.35 | EC29: =T29+AC29+AO29+BG29+BP29+BY29+CH29+CQ29+DA29+DA29+DJ29+DS29 -> 0 | ED29: =P29+Y29+AK29+AT29+BC29+BL29+BU29+CD29+CM29+CW29+DF29+DO29 -> 0 | EE29: =Q29+Z29+AL29+AU29+BD29+BM29+BV29+CE29+CN29+CX29+DG29+DP29 -> 0 | EF29: =R29+AA29+AM29+AV29+BE29+BN29+BW29+CF29+CO29+CY29+DH29+DQ29 -> 0 | EG29: =V29+AE29+AQ29+AZ29+BI29+BR29+CA29+CJ29+CS29+DC29+DL29+DU29 -> 0
A30: =ROW()-2 -> 28 | B30: 孙唯嘉 | C30: 上海 | D30: 产研二部 | E30: 业务管理一组 | F30: 产品主管 | G30: 44788 | H30: 45292 | I30: 45658 | J30: 0 | K30: =ROUND((I30-H30)/365*5,0) -> 5 | L30: 5 | M30: =K30-L30 -> 0 | O30: 2 | S30: 3 | U30: 3 | X30: 1 | Z30: 0.5 | AD30: 2.5 | AG30: =O30+X30 -> 3 | AH30: =M30-AG30 -> -3 | AI30: =IF(AH30<0,AH30,0) -> -3 | AN30: 6 | AP30: 8.5 | AT30: 2.73 | AW30: 3.47 | BB30: 1 | BC30: 2.5 | BF30: 1.5 | BK30: 1 | BL30: 5.5 | BO30: 14.5 | BQ30: 14.5 | BX30: 2.5 | BZ30: 4 | CD30: 16.5 | CG30: 7.5 | CI30: 6 | CM30: 8 | CP30: 19 | CR30: 19 | CW30: 2 | DI30: 8 | DK30: 17.5 | DO30: 17 | DP30: 1.5 | DR30: 9.5 | DW30: =ROUND((TODAY()-I30)/365*5,2) -> 5.05 | DX30: =-AI30+AJ30+AS30+BB30+BK30+BT30+CC30+CL30+CV30+DE30+DN30 -> 5 | DY30: =DW30-DX30 -> 0.05 | DZ30: =T30+U30+AC30+AD30+AO30+AP30+AX30+AY30++BG30+BH30+BP30+BQ30+BY30+BZ30+CH30+CI30+CQ30+CR30+DA30+DB30+DJ30+DK30+DS30+DT30 -> 75 | EA30: =S30+AB30+AN30+AW30+BF30+BO30+BX30+CG30+CP30+CZ30+DI30+DR30 -> 74.97 | EB30: =J30+U30-S30+AD30-AB30+AP30-AN30+AY30-AW30+BH30-BF30+BQ30-BO30+BZ30-BX30+CI30-CG30+CR30-CP30+DB30-CZ30+DK30-DI30+DT30-DR30-CU30 -> 0.03 | EC30: =T30+AC30+AO30+BG30+BP30+BY30+CH30+CQ30+DA30+DA30+DJ30+DS30 -> 0 | ED30: =P30+Y30+AK30+AT30+BC30+BL30+BU30+CD30+CM30+CW30+DF30+DO30 -> 54.23 | EE30: =Q30+Z30+AL30+AU30+BD30+BM30+BV30+CE30+CN30+CX30+DG30+DP30 -> 2 | EF30: =R30+AA30+AM30+AV30+BE30+BN30+BW30+CF30+CO30+CY30+DH30+DQ30 -> 0 | EG30: =V30+AE30+AQ30+AZ30+BI30+BR30+CA30+CJ30+CS30+DC30+DL30+DU30 -> 0
A31: =ROW()-2 -> 29 | B31: 赵德正 | C31: 上海 | D31: 产研二部 | E31: 业务管理一组 | F31: 前端开发工程师 | G31: 45041 | H31: 45292 | I31: 45658 | J31: 8 | K31: =ROUND((I31-H31)/365*5,0) -> 5 | L31: 4.5 | M31: =K31-L31 -> 0.5 | O31: 2 | X31: 1.5 | Z31: 0.5 | AC31: 8 | AG31: =O31+X31 -> 3.5 | AH31: =M31-AG31 -> -3 | AI31: =IF(AH31<0,AH31,0) -> -3 | AO31: 21 | AP31: 8 | AS31: 2 | AW31: 8 | AX31: 8 | BH31: 8 | BV31: 1 | BZ31: 8 | CM31: 8 | CP31: 24 | DB31: 16 | DI31: 8 | DK31: 8 | DS31: 8 | DW31: =ROUND((TODAY()-I31)/365*5,2) -> 5.05 | DX31: =-AI31+AJ31+AS31+BB31+BK31+BT31+CC31+CL31+CV31+DE31+DN31 -> 5 | DY31: =DW31-DX31 -> 0.05 | DZ31: =T31+U31+AC31+AD31+AO31+AP31+AX31+AY31++BG31+BH31+BP31+BQ31+BY31+BZ31+CH31+CI31+CQ31+CR31+DA31+DB31+DJ31+DK31+DS31+DT31 -> 93 | EA31: =S31+AB31+AN31+AW31+BF31+BO31+BX31+CG31+CP31+CZ31+DI31+DR31 -> 40 | EB31: =J31+U31-S31+AD31-AB31+AP31-AN31+AY31-AW31+BH31-BF31+BQ31-BO31+BZ31-BX31+CI31-CG31+CR31-CP31+DB31-CZ31+DK31-DI31+DT31-DR31-CU31 -> 16 | EC31: =T31+AC31+AO31+BG31+BP31+BY31+CH31+CQ31+DA31+DA31+DJ31+DS31 -> 37 | ED31: =P31+Y31+AK31+AT31+BC31+BL31+BU31+CD31+CM31+CW31+DF31+DO31 -> 8 | EE31: =Q31+Z31+AL31+AU31+BD31+BM31+BV31+CE31+CN31+CX31+DG31+DP31 -> 1.5 | EF31: =R31+AA31+AM31+AV31+BE31+BN31+BW31+CF31+CO31+CY31+DH31+DQ31 -> 0 | EG31: =V31+AE31+AQ31+AZ31+BI31+BR31+CA31+CJ31+CS31+DC31+DL31+DU31 -> 0
A32: =ROW()-2 -> 30 | B32: 王澜滔 | C32: 上海 | D32: 业务一部 | E32: 市场渠道组 | F32: 平面设计 | G32: 43311 | H32: 45292 | I32: 45658 | J32: 4.5 | K32: =ROUND((I32-H32)/365*5,0) -> 5 | L32: 0 | M32: =K32-L32 -> 5 | O32: 4 | S32: 2.5 | X32: 1 | AG32: =O32+X32 -> 5 | AH32: =M32-AG32 -> 0 | AI32: =IF(AH32<0,AH32,0) -> 0 | AS32: 1 | AU32: 1 | BF32: 1 | BK32: 1 | BT32: 1 | CL32: 1 | CM32: 24 | DW32: =ROUND((TODAY()-I32)/365*5,2) -> 5.05 | DX32: =-AI32+AJ32+AS32+BB32+BK32+BT32+CC32+CL32+CV32+DE32+DN32 -> 4 | DY32: =DW32-DX32 -> 1.05 | DZ32: =T32+U32+AC32+AD32+AO32+AP32+AX32+AY32++BG32+BH32+BP32+BQ32+BY32+BZ32+CH32+CI32+CQ32+CR32+DA32+DB32+DJ32+DK32+DS32+DT32 -> 0 | EA32: =S32+AB32+AN32+AW32+BF32+BO32+BX32+CG32+CP32+CZ32+DI32+DR32 -> 3.5 | EB32: =J32+U32-S32+AD32-AB32+AP32-AN32+AY32-AW32+BH32-BF32+BQ32-BO32+BZ32-BX32+CI32-CG32+CR32-CP32+DB32-CZ32+DK32-DI32+DT32-DR32-CU32 -> 1 | EC32: =T32+AC32+AO32+BG32+BP32+BY32+CH32+CQ32+DA32+DA32+DJ32+DS32 -> 0 | ED32: =P32+Y32+AK32+AT32+BC32+BL32+BU32+CD32+CM32+CW32+DF32+DO32 -> 24 | EE32: =Q32+Z32+AL32+AU32+BD32+BM32+BV32+CE32+CN32+CX32+DG32+DP32 -> 1 | EF32: =R32+AA32+AM32+AV32+BE32+BN32+BW32+CF32+CO32+CY32+DH32+DQ32 -> 0 | EG32: =V32+AE32+AQ32+AZ32+BI32+BR32+CA32+CJ32+CS32+DC32+DL32+DU32 -> 0
A33: =ROW()-2 -> 31 | B33: 王依 | C33: 上海 | D33: 产研一部 | E33: 教育三组 | F33: UI设计师 | G33: 43381 | H33: 45292 | I33: 45658 | J33: 1.5 | K33: =ROUND((I33-H33)/365*5,0) -> 5 | L33: 2 | M33: =K33-L33 -> 3 | R33: 0.5 | S33: 1.5 | X33: 3 | AA33: 0.5 | AG33: =O33+X33 -> 3 | AH33: =M33-AG33 -> 0 | AI33: =IF(AH33<0,AH33,0) -> 0 | AJ33: 0.5 | AM33: 0.5 | AU33: 6 | AV33: 0.5 | BD33: 1 | BE33: 1 | BN33: 1 | DW33: =ROUND((TODAY()-I33)/365*5,2) -> 5.05 | DX33: =-AI33+AJ33+AS33+BB33+BK33+BT33+CC33+CL33+CV33+DE33+DN33 -> 0.5 | DY33: =DW33-DX33 -> 4.55 | DZ33: =T33+U33+AC33+AD33+AO33+AP33+AX33+AY33++BG33+BH33+BP33+BQ33+BY33+BZ33+CH33+CI33+CQ33+CR33+DA33+DB33+DJ33+DK33+DS33+DT33 -> 0 | EA33: =S33+AB33+AN33+AW33+BF33+BO33+BX33+CG33+CP33+CZ33+DI33+DR33 -> 1.5 | EB33: =J33+U33-S33+AD33-AB33+AP33-AN33+AY33-AW33+BH33-BF33+BQ33-BO33+BZ33-BX33+CI33-CG33+CR33-CP33+DB33-CZ33+DK33-DI33+DT33-DR33-CU33 -> 0 | EC33: =T33+AC33+AO33+BG33+BP33+BY33+CH33+CQ33+DA33+DA33+DJ33+DS33 -> 0 | ED33: =P33+Y33+AK33+AT33+BC33+BL33+BU33+CD33+CM33+CW33+DF33+DO33 -> 0 | EE33: =Q33+Z33+AL33+AU33+BD33+BM33+BV33+CE33+CN33+CX33+DG33+DP33 -> 7 | EF33: =R33+AA33+AM33+AV33+BE33+BN33+BX33+CF33+CO33+CY33+DH33+DQ33 -> 4 | EG33: =V33+AE33+AQ33+AZ33+BI33+BR33+CA33+CJ33+CS33+DC33+DL33+DU33 -> 0
A34: =ROW()-2 -> 32 | B34: 郝惠军 | C34: 上海 | D34: 产研一部 | E34: 教育一组 | F34: 设计主管 | G34: 43972 | H34: 45292 | I34: 45658 | J34: 43 | K34: =ROUND((I34-H34)/365*5,0) -> 5 | L34: 5 | M34: =K34-L34 -> 0 | O34: 5 | S34: 11 | T34: 8 | U34: 8 | Z34: 2 | AB34: 4.5 | AG34: =O34+X34 -> 5 | AH34: =M34-AG34 -> -5 | AI34: =IF(AH34<0,AH34,0) -> -5 | AN34: 9.5 | AO34: 8 | AP34: 8 | AW34: 8 | AX34: 5.5 | BF34: 3 | BG34: 8 | BH34: 17.5 | BO34: 6 | BQ34: 3.5 | BX34: 1 | BZ34: 8 | CH34: 16 | CI34: 7.5 | CP34: 20.5 | CZ34: 5 | DJ34: 8 | DK34: 3.5 | DR34: 4 | DS34: 8 | DT34: 22.5 | DW34: =ROUND((TODAY()-I34)/365*5,2) -> 5.05 | DX34: =-AI34+AJ34+AS34+BB34+BK34+BT34+CC34+CL34+CV34+DE34+DN34 -> 5 | DY34: =DW34-DX34 -> 0.05 | DZ34: =T34+U34+AC34+AD34+AO34+AP34+AX34+AY34++BG34+BH34+BP34+BQ34+BY34+BZ34+CH34+CI34+CQ34+CR34+DA34+DB34+DJ34+DK34+DS34+DT34 -> 140 | EA34: =S34+AB34+AN34+AW34+BF34+BO34+BX34+CG34+CP34+CZ34+DI34+DR34 -> 72.5 | EB34: =J34+U34-S34+AD34-AB34+AP34-AN34+AY34-AW34+BH34-BF34+BQ34-BO34+BZ34-BX34+CI34-CG34+CR34-CP34+DB34-CZ34+DK34-DI34+DT34-DR34-CU34 -> 49 | EC34: =T34+AC34+AO34+BG34+BP34+BY34+CH34+CQ34+DA34+DA34+DJ34+DS34 -> 56 | ED34: =P34+Y34+AK34+AT34+BC34+BL34+BU34+CD34+CM34+CW34+DF34+DO34 -> 0 | EE34: =Q34+Z34+AL34+AU34+BD34+BM34+BV34+CE34+CN34+CX34+DG34+DP34 -> 2 | EF34: =R34+AA34+AM34+AV34+BE34+BN34+BW34+CF34+CO34+CY34+DH34+DQ34 -> 0 | EG34: =V34+AE34+AQ34+AZ34+BI34+BR34+CA34+CJ34+CS34+DC34+DL34+DU34 -> 0
A35: =ROW()-2 -> 33 | B35: 张潭辉 | C35: 上海 | D35: 产研二部 | E35: 业务管理一组 | F35: UI设计师 | G35: 43972 | H35: 45292 | I35: 45658 | J35: 8 | K35: =ROUND((I35-H35)/365*5,0) -> 5 | L35: 4.5 | M35: =K35-L35 -> 0.5 | X35: 0.5 | AG35: =O35+X35 -> 0.5 | AH35: =M35-AG35 -> 0 | AI35: =IF(AH35<0,AH35,0) -> 0 | AN35: 4 | AS35: 4 | BB35: 0.5 | BF35: 4 | CC35: 0.5 | CD35: 12 | CM35: 8 | DF35: 24 | DW35: =ROUND((TODAY()-I35)/365*5,2) -> 5.05 | DX35: =-AI35+AJ35+AS35+BB35+BK35+BT35+CC35+CL35+CV35+DE35+DN35 -> 5 | DY35: =DW35-DX35 -> 0.05 | DZ35: =T35+U35+AC35+AD35+AO35+AP35+AX35+AY35++BG35+BH35+BP35+BQ35+BY35+BZ35+CH35+CI35+CQ35+CR35+DA35+DB35+DJ35+DK35+DS35+DT35 -> 0 | EA35: =S35+AB35+AN35+AW35+BF35+BO35+BX35+CG35+CP35+CZ35+DI35+DR35 -> 8 | EB35: =J35+U35-S35+AD35-AB35+AP35-AN35+AY35-AW35+BH35-BF35+BQ35-BO35+BZ35-BX35+CI35-CG35+CR35-CP35+DB35-CZ35+DK35-DI35+DT35-DR35-CU35 -> 0 | EC35: =T35+AC35+AO35+BG35+BP35+BY35+CH35+CQ35+DA35+DA35+DJ35+DS35 -> 0 | ED35: =P35+Y35+AK35+AT35+BC35+BL35+BU35+CD35+CM35+CW35+DF35+DO35 -> 44 | EE35: =Q35+Z35+AL35+AU35+BD35+BM35+BV35+CE35+CN35+CX35+DG35+DP35 -> 0 | EF35: =R35+AA35+AM35+AV35+BE35+BN35+BW35+CF35+CO35+CY35+DH35+DQ35 -> 0 | EG35: =V35+AE35+AQ35+AZ35+BI35+BR35+CA35+CJ35+CS35+DC35+DL35+DU35 -> 0
A36: =ROW()-2 -> 34 | B36: 测试王艳 | C36: 上海 | D36: 产研一部 | E36: / | F36: 测试总监 | G36: 44025 | H36: 45292 | I36: 45658 | J36: 0 | K36: =ROUND((I36-H36)/365*5,0)*3 -> 15 | L36: 12 | M36: =K36-L36 -> 3 | O36: 2 | X36: 1 | AG36: =O36+X36 -> 3 | AH36: =M36-AG36 -> 0 | AI36: =IF(AH36<0,AH36,0) -> 0 | AS36: 1 | BK36: 1 | BT36: 1 | DE36: 2 | DN36: 1 | DS36: 16 | DW36: =ROUND((TODAY()-I36)/365*5,2)*3 -> 15.15 | DX36: =-AI36+AJ36+AS36+BB36+BK36+BT36+CC36+CL36+CV36+DE36+DN36 -> 6 | DY36: =DW36-DX36 -> 9.15 | DZ36: =T36+U36+AC36+AD36+AO36+AP36+AX36+AY36++BG36+BH36+BP36+BQ36+BY36+BZ36+CH36+CI36+CQ36+CR36+DA36+DB36+DJ36+DK36+DS36+DT36 -> 16 | EA36: =S36+AB36+AN36+AW36+BF36+BO36+BX36+CG36+CP36+CZ36+DI36+DR36 -> 0 | EB36: =J36+U36-S36+AD36-AB36+AP36-AN36+AY36-AW36+BH36-BF36+BQ36-BO36+BZ36-BX36+CI36-CG36+CR36-CP36+DB36-CZ36+DK36-DI36+DT36-DR36-CU36 -> 0 | EC36: =T36+AC36+AO36+BG36+BP36+BY36+CH36+CQ36+DA36+DA36+DJ36+DS36 -> 16 | ED36: =P36+Y36+AK36+AT36+BC36+BL36+BU36+CD36+CM36+CW36+DF36+DO36 -> 0 | EE36: =Q36+Z36+AL36+AU36+BD36+BM36+BV36+CE36+CN36+CX36+DG36+DP36 -> 0 | EF36: =R36+AA36+AM36+AV36+BE36+BN36+BW36+CF36+CO36+CY36+DH36+DQ36 -> 0 | EG36: =V36+AE36+AQ36+AZ36+BI36+BR36+CA36+CJ36+CS36+DC36+DL36+DU36 -> 0
A37: =ROW()-2 -> 35 | B37: 王付佳 | C37: 上海 | D37: 产研二部 | E37: 业务管理一组 | F37: 前端开发工程师 | G37: 44067 | H37: 45292 | I37: 45658 | J37: 55.5 | K37: =ROUND((I37-H37)/365*5,0) -> 5 | L37: 5 | M37: =K37-L37 -> 0 | O37: 1 | U37: 8 | AA37: 3 | AG37: =O37+X37 -> 1 | AH37: =M37-AG37 -> -1 | AI37: =IF(AH37<0,AH37,0) -> -1 | AO37: 16 | AS37: 3 | AY37: 8 | BH37: 13.5 | BQ37: 5 | CQ37: 14.5 | CV37: 1 | DJ37: 11 | DW37: =ROUND((TODAY()-I37)/365*5,2) -> 5.05 | DX37: =-AI37+AJ37+AS37+BB37+BK37+BT37+CC37+CL37+CV37+DE37+DN37 -> 5 | DY37: =DW37-DX37 -> 0.05 | DZ37: =T37+U37+AC37+AD37+AO37+AP37+AX37+AY37++BG37+BH37+BP37+BQ37+BY37+BZ37+CH37+CI37+CQ37+CR37+DA37+DB37+DJ37+DK37+DS37+DT37 -> 76 | EA37: =S37+AB37+AN37+AW37+BF37+BO37+BX37+CG37+CP37+CZ37+DI37+DR37 -> 0 | EB37: =J37+U37-S37+AD37-AB37+AP37-AN37+AY37-AW37+BH37-BF37+BQ37-BO37+BZ37-BX37+CI37-CG37+CR37-CP37+DB37-CZ37+DK37-DI37+DT37-DR37-CU37 -> 90 | EC37: =T37+AC37+AO37+BG37+BP37+BY37+CH37+CQ37+DA37+DA37+DJ37+DS37 -> 41.5 | ED37: =P37+Y37+AK37+AT37+BC37+BL37+BU37+CD37+CM37+CW37+DF37+DO37 -> 0 | EE37: =Q37+Z37+AL37+AU37+BD37+BM37+BV37+CE37+CN37+CX37+DG37+DP37 -> 0 | EF37: =R37+AA37+AM37+AV37+BE37+BN37+BW37+CF37+CO37+CY37+DH37+DQ37 -> 3 | EG37: =V37+AE37+AQ37+AZ37+BI37+BR37+CA37+CJ37+CS37+DC37+DL37+DU37 -> 0
A38: =ROW()-2 -> 36 | B38: 赵亚楠 | C38: 上海 | D38: 产研一部 | E38: 教育三组 | F38: 测试主管 | G38: 42695 | H38: 45292 | I38: 45658 | J38: 40 | K38: =ROUND((I38-H38)/365*5,0) -> 5 | L38: 5 | M38: =K38-L38 -> 0 | AG38: =O38+X38 -> 0 | AH38: =M38-AG38 -> 0 | AI38: =IF(AH38<0,AH38,0) -> 0 | AV38: 3 | AX38: 8 | AZ38: 1.5 | BF38: 2.5 | BG38: 4 | BI38: 1.5 | BO38: 4.5 | BX38: 4 | CA38: 1.5 | CG38: 3 | CI38: 11 | CP38: 2 | CZ38: 4 | DE38: 1.5 | DI38: 2 | DK38: 23 | DR38: 0.5 | DT38: 21 | DW38: =ROUND((TODAY()-I38)/365*5,2) -> 5.05 | DX38: =-AI38+AJ38+AS38+BB38+BK38+BT38+CC38+CL38+CV38+DE38+DN38 -> 1.5 | DY38: =DW38-DX38 -> 3.55 | DZ38: =T38+U38+AC38+AD38+AO38+AP38+AX38+AY38++BG38+BH38+BP38+BQ38+BY38+BZ38+CH38+CI38+CQ38+CR38+DA38+DB38+DJ38+DK38+DS38+DT38 -> 67 | EA38: =S38+AB38+AN38+AW38+BF38+BO38+BX38+CG38+CP38+CZ38+DI38+DR38 -> 22.5 | EB38: =J38+U38-S38+AD38-AB38+AP38-AN38+AY38-AW38+BH38-BF38+BQ38-BO38+BZ38-BX38+CI38-CG38+CR38-CP38+DB38-CZ38+DK38-DI38+DT38-DR38-CU38 -> 72.5 | EC38: =T38+AC38+AO38+BG38+BP38+BY38+CH38+CQ38+DA38+DA38+DJ38+DS38 -> 4 | ED38: =P38+Y38+AK38+AT38+BC38+BL38+BU38+CD38+CM38+CW38+DF38+DO38 -> 0 | EE38: =Q38+Z38+AL38+AU38+BD38+BM38+BV38+CE38+CN38+CX38+DG38+DP38 -> 0 | EF38: =R38+AA38+AM38+AV38+BE38+BN38+BW38+CF38+CO38+CY38+DH38+DQ38 -> 3 | EG38: =V38+AE38+AQ38+AZ38+BI38+BR38+CA38+CJ38+CS38+DC38+DL38+DU38 -> 4.5
A39: =ROW()-2 -> 37 | B39: 李贵洲 | C39: 上海 | D39: 产研三部 | E39: DIM组 | F39: 研发主管（PHP） | G39: 44068 | H39: 45292 | I39: 45658 | J39: 20 | K39: =ROUND((I39-H39)/365*5,0) -> 5 | L39: 1 | M39: =K39-L39 -> 4 | O39: 3 | T39: 8 | X39: 1 | AG39: =O39+X39 -> 4 | AH39: =M39-AG39 -> 0 | AI39: =IF(AH39<0,AH39,0) -> 0 | AJ39: 1 | AO39: 8 | AS39: 0.5 | BP39: 16 | BY39: 8 | CH39: 16 | CQ39: 16 | DA39: 16 | DJ39: 15 | DS39: 18 | DW39: =ROUND((TODAY()-I39)/365*5,2) -> 5.05 | DX39: =-AI39+AJ39+AS39+BB39+BK39+BT39+CC39+CL39+CV39+DE39+DN39 -> 1.5 | DY39: =DW39-DX39 -> 3.55 | DZ39: =T39+U39+AC39+AD39+AO39+AP39+AX39+AY39++BG39+BH39+BP39+BQ39+BY39+BZ39+CH39+CI39+CQ39+CR39+DA39+DB39+DJ39+DK39+DS39+DT39 -> 121 | EA39: =S39+AB39+AN39+AW39+BF39+BO39+BX39+CG39+CP39+CZ39+DI39+DR39 -> 0 | EB39: =J39+U39-S39+AD39-AB39+AP39-AN39+AY39-AW39+BH39-BF39+BQ39-BO39+BZ39-BX39+CI39-CG39+CR39-CP39+DB39-CZ39+DK39-DI39+DT39-DR39-CU39 -> 20 | EC39: =T39+AC39+AO39+BG39+BP39+BY39+CH39+CQ39+DA39+DA39+DJ39+DS39 -> 137 | ED39: =P39+Y39+AK39+AT39+BC39+BL39+BU39+CD39+CM39+CW39+DF39+DO39 -> 0 | EE39: =Q39+Z39+AL39+AU39+BD39+BM39+BV39+CE39+CN39+CX39+DG39+DP39 -> 0 | EF39: =R39+AA39+AM39+AV39+BE39+BN39+BW39+CF39+CO39+CY39+DH39+DQ39 -> 0 | EG39: =V39+AE39+AQ39+AZ39+BI39+BR39+CA39+CJ39+CS39+DC39+DL39+DU39 -> 0
A40: =ROW()-2 -> 38 | B40: 宛超 | C40: 上海 | D40: 产研三部 | E40: 业务管理二组 | F40: PHP开发工程师 | G40: 43626 | H40: 45292 | I40: 45658 | J40: 25 | K40: =ROUND((I40-H40)/365*5,0) -> 5 | L40: 5 | M40: =K40-L40 -> 0 | U40: 8.5 | AG40: =O40+X40 -> 0 | AH40: =M40-AG40 -> 0 | AI40: =IF(AH40<0,AH40,0) -> 0 | AN40: 8 | AO40: 26.5 | AS40: 0.5 | AW40: 8 | AX40: 16 | BP40: 8 | BT40: 0.5 | BX40: 1.5 | BY40: 19 | CG40: 8 | CH40: 8 | DI40: 4 | DJ40: 16 | DW40: =ROUND((TODAY()-I40)/365*5,2) -> 5.05 | DX40: =-AI40+AJ40+AS40+BB40+BK40+BT40+CC40+CL40+CV40+DE40+DN40 -> 1 | DY40: =DW40-DX40 -> 4.05 | DZ40: =T40+U40+AC40+AD40+AO40+AP40+AX40+AY40++BG40+BH40+BP40+BQ40+BY40+BZ40+CH40+CI40+CQ40+CR40+DA40+DB40+DJ40+DK40+DS40+DT40 -> 102 | EA40: =S40+AB40+AN40+AW40+BF40+BO40+BX40+CG40+CP40+CZ40+DI40+DR40 -> 29.5 | EB40: =J40+U40-S40+AD40-AB40+AP40-AN40+AY40-AW40+BH40-BF40+BQ40-BO40+BZ40-BX40+CI40-CG40+CR40-CP40+DB40-CZ40+DK40-DI40+DT40-DR40-CU40 -> 4 | EC40: =T40+AC40+AO40+BG40+BP40+BY40+CH40+CQ40+DA40+DA40+DJ40+DS40 -> 77.5 | ED40: =P40+Y40+AK40+AT40+BC40+BL40+BU40+CD40+CM40+CW40+DF40+DO40 -> 0 | EE40: =Q40+Z40+AL40+AU40+BD40+BM40+BV40+CE40+CN40+CX40+DG40+DP40 -> 0 | EF40: =R40+AA40+AM40+AV40+BE40+BN40+BW40+CF40+CO40+CY40+DH40+DQ40 -> 0 | EG40: =V40+AE40+AQ40+AZ40+BI40+BR40+CA40+CJ40+CS40+DC40+DL40+DU40 -> 0
...

Sheet 2025年假调整人员
A1: 序号 | B1: 姓名 | C1: 区域 | D1: 部门 | E1: 组别 | F1: 岗位 | G1: 入职日期 | H1: 2025年假系统调整
A2: =ROW()-1 -> 1 | B2: 卢佳 | C2: 上海 | D2: 行政部 | E2: / | F2: 行政主管 | G2: 44144 | H2: 年假调整为10天
A3: =ROW()-1 -> 2 | B3: 孙玉凤 | C3: 上海 | D3: 人力资源部 | E3: / | F3: 人力资源总监 | G3: 43192 | H3: 年假调整为10天
A4: =ROW()-1 -> 3 | B4: 吴俊志 | C4: 上海 | D4: 产研一部 | E4: 教育一组 | F4: 产品部主管 | G4: 44350 | H4: 年假调整为10天
A5: =ROW()-1 -> 4 | B5: 蒲科辉 | C5: 上海 | D5: 产研一部 | E5: 0 | F5: 研发副总 | G5: 42005 | H5: 年假调整为10天
A6: =ROW()-1 -> 5 | B6: 董皊 | C6: 上海 | D6: 上海营销一部 | E6: 董皊组 | F6: 运营主管 | G6: 43619 | H6: 年假调整为10天
A7: =ROW()-1 -> 6 | B7: 蒋杰 | C7: 上海 | D7: 行政部 | E7: 0 | F7: 行政总监&营销总监 | G7: 42005 | H7: 年假调整为10天
A8: =ROW()-1 -> 7 | B8: 吴菲 | C8: 上海 | D8: 上海营销二部 | E8: 吴菲组 | F8: 运营主管 | G8: 43384 | H8: 年假调整为10天
A9: =ROW()-1 -> 8 | B9: 陈慧 | C9: 上海 | D9: 上海营销二部 | E9: 吴菲组 | F9: 运营专员 | G9: 43906 | H9: 年假调整为10天
A10: =ROW()-1 -> 9 | B10: 吴阳明 | C10: 厦门 | D10: 产研一部 | E10: PC组 | F10: 运营总监 | G10: 42005 | H10: 年假调整为10天
A11: =ROW()-1 -> 10 | B11: 林碧虹 | C11: 厦门 | D11: 厦门内容部 | E11: 林碧虹组 | F11: 内容主管 | G11: 43969 | H11: 年假调整为10天
A12: =ROW()-1 -> 11 | B12: 叶聪玲 | C12: 长泰 | D12: 厦门内容部 | E12: 叶聪玲组 | F12: 内容主管 | G12: 42355 | H12: 年假调整为10天
A13: =ROW()-1 -> 12 | B13: 蔡惠娜 | C13: 长泰 | D13: 厦门内容部 | E13: 叶聪玲组 | F13: 内容编辑 | G13: 42788 | H13: 年假调整为10天
A14: =ROW()-1 -> 13 | B14: 郑建珍 | C14: 长泰 | D14: 厦门内容部 | E14: 叶聪玲组 | F14: 内容编辑 | G14: 43474 | H14: 年假调整为10天
A15: =ROW()-1 -> 14 | B15: 汤章溢 | C15: 厦门 | D15: 厦门营销二部 | E15: 汤章溢组 | F15: 营销总监 | G15: 42416 | H15: 年假调整为10天
A16: =ROW()-1 -> 15 | B16: 许财杰 | C16: 厦门 | D16: 厦门营销二部 | E16: 许财杰组 | F16: 销售主管 | G16: 44060 | H16: 年假调整为10天
A17: =ROW()-1 -> 16 | B17: 李梦阳 | C17: 厦门 | D17: 厦门营销一部 | E17: 李梦阳组 | F17: 运营主管 | G17: 42943 | H17: 年假调整为10天
A18: =ROW()-1 -> 17 | B18: 王家盛 | C18: 厦门 | D18: 厦门营销一部 | E18: 李梦阳组 | F18: 运营专员 | G18: 43556 | H18: 年假调整为10天
A19: =ROW()-1 -> 18 | B19: 孙敏 | C19: 厦门 | D19: 厦门营销一部 | E19: 李梦阳组 | F19: 运营专员 | G19: 43619 | H19: 年假调整为10天
... A21: =ROW()-1 -> 20 | B21: 刘丽 | C21: 长沙 | D21: 长沙内容部 | E21: 刘丽组 | F21: 内容主管 | G21: 43992 | H21: 年假调整为10天
A22: =ROW()-1 -> 21 | B22: 丁辉 | C22: 长沙 | D22: 0 | E22: 0 | F22: 营销总监 | G22: 41640 | H22: 年假调整为10天
A23: =ROW()-1 -> 22 | B23: 乐敏 | C23: 上海 | D23: 业务一部 | E23: 美术事业部 | F23: 美术教研主管 | G23: 45125 | H23: 年假调整为10天
A24: =ROW()-1 -> 23 | B24: 裴芳芳 | C24: 厦门 | D24: 业务一部 | E24: 阅读事业部 | F24: 阅读教研主管 | G24: 45397 | H24: 年假调整为10天
A25: =ROW()-1 -> 24 | B25: 黄娜君 | C25: 厦门 | D25: 厦门营销一部 | E25: 刘益先组 | F25: 资深销售二级 | G25: 43627 | H25: 年假调整为10天
A26: =ROW()-1 -> 25 | B26: 刘鑫 | C26: 上海 | D26: 业务一部 | E26: 新媒体组 | F26: 新媒体主管 | G26: 44159 | H26: 年假调整为10天
A27: =ROW()-1 -> 26 | B27: 曹佳军 | C27: 上海 | D27: 业务一部 | E27: 业务运营组 | F27: 业务运营 | G27: 45145 | H27: 年假调整为10天
A28: =ROW()-1 -> 27 | B28: 李海侠 | C28: 上海 | D28: 产研一部 | E28: 教育三组 | F28: Android开发工程师 | G28: 44267 | H28: 年假调整为10天
A29: =ROW()-1 -> 28 | B29: 刘莹 | C29: 长沙 | D29: 长沙内容部 | E29: 刘莹组 | F29: 内容主管 | G29: 43922 | H29: 年假调整为10天
A30: =ROW()-1 -> 29 | B30: 彭朝磊 | C30: 上海 | D30: 上海营销二部 | E30: 刘伦星组 | F30: 销售专员 | G30: 45553 | H30: 年假调整为10天
A31: =ROW()-1 -> 30 | B31: 刘伦星 | C31: 上海 | D31: 上海营销二部 | E31: 刘伦星组 | F31: 销售主管(中级) | G31: 43920 | H31: 年假调整为10天
A32: =ROW()-1 -> 31 | B32: 黄娜 | C32: 上海 | D32: 上海营销三部 | E32: 李梦组 | F32: 运营专员 | G32: 45341 | H32: 年假调整为10天
A33: =ROW()-1 -> 32 | B33: 杜雅妮 | C33: 厦门 | D33: 厦门营销二部 | E33: 杜雅妮组 | F33: 运营主管 | G33: 43368 | H33: 年假调整为10天
A34: =ROW()-1 -> 33 | B34: 陈珊 | C34: 厦门 | D34: 厦门营销二部 | E34: 杜雅妮组 | F34: 运营专员 | G34: 43928 | H34: 年假调整为10天
... A40: =ROW()-1 -> 39 | B40: 胡军 | C40: 上海 | D40: 产研二部 | E40: 架构组 | F40: 研发主管 | G40: 44256 | H40: 年假调整为10天
A41: =ROW()-1 -> 40 | B41: 吴俊宇 | C41: 上海 | D41: 业务一部 | E41: 数学事业部 | F41: 数学事业部主管 | G41: 45719 | H41: 年假调整为10天 | I41: 增加4天
A42: =ROW()-1 -> 41 | B42: 屈翎野 | C42: 上海 | D42: 业务一部 | E42: 新媒体组 | F42: 新媒体专员 | G42: 43185 | H42: 年假调整为10天 | I42: 增加5天
A43: =ROW()-1 -> 42 | B43: 许欣瑜 | C43: 厦门 | D43: 人力资源部 | E43: / | F43: 人事行政 | G43: 45356 | H43: 年假调整为10天 | I43: 增加3天
A44: =ROW()-1 -> 43 | B44: 焦少平 | C44: 上海 | D44: 产研二部 | E44: 架构组 | F44: Java工程师 | G44: 45352 | H44: 年假调整为10天 | I44: 增加5天
A45: =ROW()-1 -> 44 | B45: 饶洁 | C45: 上海 | D45: 业务一部 | E45: 业务运营组 | F45: 业务主管 | G45: 43696 | H45: 年假调整为10天 | I45: 增加5天
A46: =ROW()-1 -> 45 | B46: 方志海 | C46: 厦门 | D46: 业务一部 | E46: 书法事业部 | F46: 书法高级教研 | G46: 45118 | H46: 年假调整为10天 | I46: 增加2.5天
...

Sheet 核对
B1: 姓名 | C1: 11月
A2: 序号 | C2: 年假 | D2: 系统 | E2: 异常 | F2: 事假h | G2: 系统 | H2: 异常 | I2: 病假 | J2: 系统27 | K2: 异常 | L2: 调休 | M2: 调休系统 | N2: 异常 | O2: 加班 加班费 | P2: 系统36 | Q2: 异常 | R2: 加班 转调休 | S2: 系统39 | T2: 异常
A3: =ROW()-2 -> 1 | B3: 刘其坚 | D3: =VLOOKUP($B3,[10]月度汇总!$A:$AM,22,0) -> 0 | G3: =VLOOKUP($B3,[10]月度汇总!$A:$AM,23,0) -> 0 | H3: =F3-G3 -> 0 | J3: =VLOOKUP($B3,[10]月度汇总!$A:$AM,24,0) -> 0 | K3: =I3-J3 -> 0 | M3: =VLOOKUP($B3,[10]月度汇总!$A:$AM,25,0) -> 0 | N3: =L3-M3 -> 0 | P3: =VLOOKUP($B3,[10]月度汇总!$A:$AM,35,0) -> 0 | Q3: =O3-P3 -> 0 | S3: =VLOOKUP($B3,[10]月度汇总!$A:$AM,38,0) -> 0 | T3: =R3-S3 -> 0
A4: =ROW()-2 -> 2 | B4: 刘玉 | D4: =VLOOKUP(B4,[10]月度汇总!$A:$AM,22,0) -> 0.5 | E4: =C4-D4 -> -0.5 | G4: =VLOOKUP($B4,[10]月度汇总!$A:$AM,23,0) -> 0 | H4: =F4-G4 -> 0 | J4: =VLOOKUP($B4,[10]月度汇总!$A:$AM,24,0) -> 0 | K4: =I4-J4 -> 0 | M4: =VLOOKUP($B4,[10]月度汇总!$A:$AM,25,0) -> 0 | N4: =L4-M4 -> 0 | O4: 5 | P4: =VLOOKUP($B4,[10]月度汇总!$A:$AM,35,0) -> 0 | Q4: =O4-P4 -> 5 | R4: 6 | S4: =VLOOKUP($B4,[10]月度汇总!$A:$AM,38,0) -> 0 | T4: =R4-S4 -> 6
A5: =ROW()-2 -> 3 | B5: 胡生娜 | D5: =VLOOKUP(B5,[10]月度汇总!$A:$AM,22,0) -> 0 | E5: =C5-D5 -> 0 | G5: =VLOOKUP($B5,[10]月度汇总!$A:$AM,23,0) -> 0 | H5: =F5-G5 -> 0 | J5: =VLOOKUP($B5,[10]月度汇总!$A:$AM,24,0) -> 0 | K5: =I5-J5 -> 0 | L5: 2 | M5: =VLOOKUP($B5,[10]月度汇总!$A:$AM,25,0) -> 0 | N5: =L5-M5 -> 2 | P5: =VLOOKUP($B5,[10]月度汇总!$A:$AM,35,0) -> 0 | Q5: =O5-P5 -> 0 | S5: =VLOOKUP($B5,[10]月度汇总!$A:$AM,38,0) -> 0 | T5: =R5-S5 -> 0
A6: =ROW()-2 -> 4 | B6: 邓雅芳 | D6: =VLOOKUP(B6,[10]月度汇总!$A:$AM,22,0) -> 11.65 | E6: =C6-D6 -> -11.65 | F6: 21.5 | G6: =VLOOKUP($B6,[10]月度汇总!$A:$AM,23,0) -> 0 | H6: =F6-G6 -> 21.5 | J6: =VLOOKUP($B6,[10]月度汇总!$A:$AM,24,0) -> 21.5 | K6: =I6-J6 -> -21.5 | L6: 1 | M6: =VLOOKUP($B6,[10]月度汇总!$A:$AM,25,0) -> 0 | N6: =L6-M6 -> 1 | P6: =VLOOKUP($B6,[10]月度汇总!$A:$AM,35,0) -> 0 | Q6: =O6-P6 -> 0 | S6: =VLOOKUP($B6,[10]月度汇总!$A:$AM,38,0) -> 0 | T6: =R6-S6 -> 0
A7: =ROW()-2 -> 5 | B7: 周彤 | D7: =VLOOKUP(B7,[10]月度汇总!$A:$AM,22,0) -> 0 | E7: =C7-D7 -> 0 | G7: =VLOOKUP($B7,[10]月度汇总!$A:$AM,23,0) -> 0 | H7: =F7-G7 -> 0 | J7: =VLOOKUP($B7,[10]月度汇总!$A:$AM,24,0) -> 0 | K7: =I7-J7 -> 0 | L7: 2 | M7: =VLOOKUP($B7,[10]月度汇总!$A:$AM,25,0) -> 0 | N7: =L7-M7 -> 2 | P7: =VLOOKUP($B7,[10]月度汇总!$A:$AM,35,0) -> 0 | Q7: =O7-P7 -> 0 | S7: =VLOOKUP($B7,[10]月度汇总!$A:$AM,38,0) -> 0 | T7: =R7-S7 -> 0
A8: =ROW()-2 -> 6 | B8: 张晓伟 | D8: =VLOOKUP(B8,[10]月度汇总!$A:$AM,22,0) -> 0 | E8: =C8-D8 -> 0 | G8: =VLOOKUP($B8,[10]月度汇总!$A:$AM,23,0) -> 0 | H8: =F8-G8 -> 0 | J8: =VLOOKUP($B8,[10]月度汇总!$A:$AM,24,0) -> 0 | K8: =I8-J8 -> 0 | M8: =VLOOKUP($B8,[10]月度汇总!$A:$AM,25,0) -> 0 | N8: =L8-M8 -> 0 | P8: =VLOOKUP($B8,[10]月度汇总!$A:$AM,35,0) -> 0 | Q8: =O8-P8 -> 0 | S8: =VLOOKUP($B8,[10]月度汇总!$A:$AM,38,0) -> 0 | T8: =R8-S8 -> 0
A9: =ROW()-2 -> 7 | B9: 卢佳 | D9: =VLOOKUP(B9,[10]月度汇总!$A:$AM,22,0) -> 2.5 | E9: =C9-D9 -> -2.5 | F9: 2 | G9: =VLOOKUP($B9,[10]月度汇总!$A:$AM,23,0) -> 0 | H9: =F9-G9 -> 2 | J9: =VLOOKUP($B9,[10]月度汇总!$A:$AM,24,0) -> 2 | K9: =I9-J9 -> -2 | M9: =VLOOKUP($B9,[10]月度汇总!$A:$AM,25,0) -> 0 | N9: =L9-M9 -> 0 | P9: =VLOOKUP($B9,[10]月度汇总!$A:$AM,35,0) -> 0 | Q9: =O9-P9 -> 0 | S9: =VLOOKUP($B9,[10]月度汇总!$A:$AM,38,0) -> 0 | T9: =R9-S9 -> 0
A10: =ROW()-2 -> 8 | B10: 周子蛟 | D10: =VLOOKUP(B10,[10]月度汇总!$A:$AM,22,0) -> 37.82 | E10: =C10-D10 -> -37.82 | G10: =VLOOKUP($B10,[10]月度汇总!$A:$AM,23,0) -> 0 | H10: =F10-G10 -> 0 | I10: 2 | J10: =VLOOKUP($B10,[10]月度汇总!$A:$AM,24,0) -> 0 | K10: =I10-J10 -> 2 | L10: 10.5 | M10: =VLOOKUP($B10,[10]月度汇总!$A:$AM,25,0) -> 2 | N10: =L10-M10 -> 8.5 | P10: =VLOOKUP($B10,[10]月度汇总!$A:$AM,35,0) -> 0 | Q10: =O10-P10 -> 0 | R10: 6 | S10: =VLOOKUP($B10,[10]月度汇总!$A:$AM,38,0) -> 0 | T10: =R10-S10 -> 6
A11: =ROW()-2 -> 9 | B11: 胡惜文 | C11: 1 | D11: =VLOOKUP(B11,[10]月度汇总!$A:$AM,22,0) -> 21.5 | E11: =C11-D11 -> -20.5 | G11: =VLOOKUP($B11,[10]月度汇总!$A:$AM,23,0) -> 1 | H11: =F11-G11 -> -1 | J11: =VLOOKUP($B11,[10]月度汇总!$A:$AM,24,0) -> 0 | K11: =I11-J11 -> 0 | M11: =VLOOKUP($B11,[10]月度汇总!$A:$AM,25,0) -> 0 | N11: =L11-M11 -> 0 | P11: =VLOOKUP($B11,[10]月度汇总!$A:$AM,35,0) -> 0 | Q11: =O11-P11 -> 0 | R11: 2 | S11: =VLOOKUP($B11,[10]月度汇总!$A:$AM,38,0) -> 0 | T11: =R11-S11 -> 2
A12: =ROW()-2 -> 10 | B12: 何尚杰 | D12: =VLOOKUP(B12,[10]月度汇总!$A:$AM,22,0) -> 25.75 | E12: =C12-D12 -> -25.75 | G12: =VLOOKUP($B12,[10]月度汇总!$A:$AM,23,0) -> 0 | H12: =F12-G12 -> 0 | J12: =VLOOKUP($B12,[10]月度汇总!$A:$AM,24,0) -> 0 | K12: =I12-J12 -> 0 | L12: 12 | M12: =VLOOKUP($B12,[10]月度汇总!$A:$AM,25,0) -> 0 | N12: =L12-M12 -> 12 | P12: =VLOOKUP($B12,[10]月度汇总!$A:$AM,35,0) -> 0 | Q12: =O12-P12 -> 0 | R12: 8 | S12: =VLOOKUP($B12,[10]月度汇总!$A:$AM,38,0) -> 0 | T12: =R12-S12 -> 8
A13: =ROW()-2 -> 11 | B13: 饶洁 | D13: =VLOOKUP(B13,[10]月度汇总!$A:$AM,22,0) -> 24 | E13: =C13-D13 -> -24 | G13: =VLOOKUP($B13,[10]月度汇总!$A:$AM,23,0) -> 0 | H13: =F13-G13 -> 0 | J13: =VLOOKUP($B13,[10]月度汇总!$A:$AM,24,0) -> 0 | K13: =I13-J13 -> 0 | M13: =VLOOKUP($B13,[10]月度汇总!$A:$AM,25,0) -> 0 | N13: =L13-M13 -> 0 | P13: =VLOOKUP($B13,[10]月度汇总!$A:$AM,35,0) -> 0 | Q13: =O13-P13 -> 0 | S13: =VLOOKUP($B13,[10]月度汇总!$A:$AM,38,0) -> 0 | T13: =R13-S13 -> 0
